{
  "version": 8,
  "blockIdVersion": 11,
  "anchorX": 0,
  "anchorY": 0,
  "anchorZ": 0,
  "blocks": [
    {
      "x": -2,
      "y": 3,
      "z": 0,
      "name": "Te_Whenua_Plant_Rimu_Leaves",
      "support": 15
    },
    {
      "x": -1,
      "y": 3,
      "z": -1,
      "name": "Te_Whenua_Plant_Rimu_Leaves",
      "support": 15
    },
    {
      "x": -1,
      "y": 4,
      "z": -1,
      "name": "Te_Whenua_Plant_Rimu_Leaves",
      "support": 15
    },
    {
      "x": -1,
      "y": 5,
      "z": -1,
      "name": "Te_Whenua_Plant_Rimu_Leaves",
      "support": 15
    },
    {
      "x": -1,
      "y": 2,
      "z": 0,
      "name": "Te_Whenua_Plant_Rimu_Leaves",
      "support": 15
    },
    {
      "x": -1,
      "y": 3,
      "z": 0,
      "name": "Te_Whenua_Plant_Rimu_Leaves",
      "support": 15
    },
    {
      "x": -1,
      "y": 4,
      "z": 0,
      "name": "Te_Whenua_Plant_Rimu_Leaves",
      "support": 15
    },
    {
      "x": -1,
      "y": 5,
      "z": 0,
      "name": "Te_Whenua_Plant_Rimu_Leaves",
      "support": 15
    },
    {
      "x": -1,
      "y": 6,
      "z": 0,
      "name": "Te_Whenua_Plant_Rimu_Leaves",
      "support": 15
    },
    {
      "x": -1,
      "y": 3,
      "z": 1,
      "name": "Te_Whenua_Plant_Rimu_Leaves",
      "support": 15
    },
    {
      "x": -1,
      "y": 4,
      "z": 1,
      "name": "Te_Whenua_Plant_Rimu_Leaves",
      "support": 15
    },
    {
      "x": -1,
      "y": 5,
      "z": 1,
      "name": "Te_Whenua_Plant_Rimu_Leaves",
      "support": 15
    },
    {
      "x": 0,
      "y": 3,
      "z": -2,
      "name": "Te_Whenua_Plant_Rimu_Leaves",
      "support": 15
    },
    {
      "x": 0,
      "y": 2,
      "z": -1,
      "name": "Te_Whenua_Plant_Rimu_Leaves",
      "support": 15
    },
    {
      "x": 0,
      "y": 3,
      "z": -1,
      "name": "Te_Whenua_Plant_Rimu_Leaves",
      "support": 15
    },
    {
      "x": 0,
      "y": 4,
      "z": -1,
      "name": "Te_Whenua_Plant_Rimu_Leaves",
      "support": 15
    },
    {
      "x": 0,
      "y": 5,
      "z": -1,
      "name": "Te_Whenua_Plant_Rimu_Leaves",
      "support": 15
    },
    {
      "x": 0,
      "y": 6,
      "z": -1,
      "name": "Te_Whenua_Plant_Rimu_Leaves",
      "support": 15
    },
    {
      "x": 0,
      "y": 0,
      "z": 0,
      "name": "Te_Whenua_Wood_Rimu_Branch_Long",
      "support": 15
    },
    {
      "x": 0,
      "y": 1,
      "z": 0,
      "name": "Te_Whenua_Wood_Rimu_Branch_Long",
      "support": 15
    },
    {
      "x": 0,
      "y": 2,
      "z": 0,
      "name": "Te_Whenua_Wood_Rimu_Branch_Long",
      "support": 15
    },
    {
      "x": 0,
      "y": 3,
      "z": 0,
      "name": "Te_Whenua_Wood_Rimu_Branch_Long",
      "support": 15
    },
    {
      "x": 0,
      "y": 4,
      "z": 0,
      "name": "Te_Whenua_Wood_Rimu_Branch_Long",
      "support": 15
    },
    {
      "x": 0,
      "y": 5,
      "z": 0,
      "name": "Te_Whenua_Wood_Rimu_Branch_Long",
      "support": 15
    },
    {
      "x": 0,
      "y": 6,
      "z": 0,
      "name": "Te_Whenua_Plant_Rimu_Leaves",
      "support": 15
    },
    {
      "x": 0,
      "y": 7,
      "z": 0,
      "name": "Te_Whenua_Plant_Rimu_Leaves",
      "support": 15
    },
    {
      "x": 0,
      "y": 2,
      "z": 1,
      "name": "Te_Whenua_Plant_Rimu_Leaves",
      "support": 15
    },
    {
      "x": 0,
      "y": 3,
      "z": 1,
      "name": "Te_Whenua_Plant_Rimu_Leaves",
      "support": 15
    },
    {
      "x": 0,
      "y": 4,
      "z": 1,
      "name": "Te_Whenua_Plant_Rimu_Leaves",
      "support": 15
    },
    {
      "x": 0,
      "y": 5,
      "z": 1,
      "name": "Te_Whenua_Plant_Rimu_Leaves",
      "support": 15
    },
    {
      "x": 0,
      "y": 6,
      "z": 1,
      "name": "Te_Whenua_Plant_Rimu_Leaves",
      "support": 15
    },
    {
      "x": 0,
      "y": 3,
      "z": 2,
      "name": "Te_Whenua_Plant_Rimu_Leaves",
      "support": 15
    },
    {
      "x": 1,
      "y": 3,
      "z": -1,
      "name": "Te_Whenua_Plant_Rimu_Leaves",
      "support": 15
    },
    {
      "x": 1,
      "y": 4,
      "z": -1,
      "name": "Te_Whenua_Plant_Rimu_Leaves",
      "support": 15
    },
    {
      "x": 1,
      "y": 5,
      "z": -1,
      "name": "Te_Whenua_Plant_Rimu_Leaves",
      "support": 15
    },
    {
      "x": 1,
      "y": 2,
      "z": 0,
      "name": "Te_Whenua_Plant_Rimu_Leaves",
      "support": 15
    },
    {
      "x": 1,
      "y": 3,
      "z": 0,
      "name": "Te_Whenua_Plant_Rimu_Leaves",
      "support": 15
    },
    {
      "x": 1,
      "y": 4,
      "z": 0,
      "name": "Te_Whenua_Plant_Rimu_Leaves",
      "support": 15
    },
    {
      "x": 1,
      "y": 5,
      "z": 0,
      "name": "Te_Whenua_Plant_Rimu_Leaves",
      "support": 15
    },
    {
      "x": 1,
      "y": 6,
      "z": 0,
      "name": "Te_Whenua_Plant_Rimu_Leaves",
      "support": 15
    },
    {
      "x": 1,
      "y": 3,
      "z": 1,
      "name": "Te_Whenua_Plant_Rimu_Leaves",
      "support": 15
    },
    {
      "x": 1,
      "y": 4,
      "z": 1,
      "name": "Te_Whenua_Plant_Rimu_Leaves",
      "support": 15
    },
    {
      "x": 1,
      "y": 5,
      "z": 1,
      "name": "Te_Whenua_Plant_Rimu_Leaves",
      "support": 15
    },
    {
      "x": 2,
      "y": 3,
      "z": 0,
      "name": "Te_Whenua_Plant_Rimu_Leaves",
      "support": 15
    }
  ]
}