{
  "version": 8,
  "blockIdVersion": 11,
  "anchorX": 0,
  "anchorY": 1,
  "anchorZ": 1,
  "blocks": [
    {
      "x": -4,
      "y": 18,
      "z": 1,
      "name": "Te_Whenua_Plant_Rimu_Leaves"
    },
    {
      "x": -4,
      "y": 19,
      "z": 1,
      "name": "Te_Whenua_Plant_Rimu_Leaves"
    },
    {
      "x": -4,
      "y": 20,
      "z": 1,
      "name": "Te_Whenua_Plant_Rimu_Leaves"
    },
    {
      "x": -4,
      "y": 27,
      "z": 1,
      "name": "Te_Whenua_Plant_Rimu_Leaves"
    },
    {
      "x": -4,
      "y": 28,
      "z": 1,
      "name": "Te_Whenua_Plant_Rimu_Leaves"
    },
    {
      "x": -4,
      "y": 29,
      "z": 1,
      "name": "Te_Whenua_Plant_Rimu_Leaves"
    },
    {
      "x": -4,
      "y": 23,
      "z": 2,
      "name": "Te_Whenua_Plant_Rimu_Leaves"
    },
    {
      "x": -4,
      "y": 24,
      "z": 2,
      "name": "Te_Whenua_Plant_Rimu_Leaves"
    },
    {
      "x": -4,
      "y": 25,
      "z": 2,
      "name": "Te_Whenua_Plant_Rimu_Leaves"
    },
    {
      "x": -3,
      "y": 19,
      "z": -2,
      "name": "Te_Whenua_Plant_Rimu_Leaves"
    },
    {
      "x": -3,
      "y": 20,
      "z": -2,
      "name": "Te_Whenua_Plant_Rimu_Leaves"
    },
    {
      "x": -3,
      "y": 21,
      "z": -2,
      "name": "Te_Whenua_Plant_Rimu_Leaves"
    },
    {
      "x": -3,
      "y": 19,
      "z": -1,
      "name": "Te_Whenua_Plant_Rimu_Leaves"
    },
    {
      "x": -3,
      "y": 20,
      "z": -1,
      "name": "Te_Whenua_Plant_Rimu_Leaves"
    },
    {
      "x": -3,
      "y": 21,
      "z": -1,
      "name": "Te_Whenua_Plant_Rimu_Leaves"
    },
    {
      "x": -3,
      "y": 18,
      "z": 0,
      "name": "Te_Whenua_Plant_Rimu_Leaves"
    },
    {
      "x": -3,
      "y": 19,
      "z": 0,
      "name": "Te_Whenua_Plant_Rimu_Leaves"
    },
    {
      "x": -3,
      "y": 20,
      "z": 0,
      "name": "Te_Whenua_Plant_Rimu_Leaves"
    },
    {
      "x": -3,
      "y": 27,
      "z": 0,
      "name": "Te_Whenua_Plant_Rimu_Leaves"
    },
    {
      "x": -3,
      "y": 28,
      "z": 0,
      "name": "Te_Whenua_Plant_Rimu_Leaves"
    },
    {
      "x": -3,
      "y": 29,
      "z": 0,
      "name": "Te_Whenua_Plant_Rimu_Leaves"
    },
    {
      "x": -3,
      "y": 16,
      "z": 1,
      "name": "Te_Whenua_Plant_Rimu_Leaves"
    },
    {
      "x": -3,
      "y": 17,
      "z": 1,
      "name": "Te_Whenua_Plant_Rimu_Leaves"
    },
    {
      "x": -3,
      "y": 18,
      "z": 1,
      "name": "Te_Whenua_Plant_Rimu_Leaves"
    },
    {
      "x": -3,
      "y": 19,
      "z": 1,
      "name": "Te_Whenua_Plant_Rimu_Leaves"
    },
    {
      "x": -3,
      "y": 20,
      "z": 1,
      "name": "Te_Whenua_Plant_Rimu_Leaves"
    },
    {
      "x": -3,
      "y": 21,
      "z": 1,
      "name": "Te_Whenua_Plant_Rimu_Leaves"
    },
    {
      "x": -3,
      "y": 23,
      "z": 1,
      "name": "Te_Whenua_Plant_Rimu_Leaves"
    },
    {
      "x": -3,
      "y": 24,
      "z": 1,
      "name": "Te_Whenua_Plant_Rimu_Leaves"
    },
    {
      "x": -3,
      "y": 25,
      "z": 1,
      "name": "Te_Whenua_Plant_Rimu_Leaves"
    },
    {
      "x": -3,
      "y": 26,
      "z": 1,
      "name": "Te_Whenua_Plant_Rimu_Leaves"
    },
    {
      "x": -3,
      "y": 27,
      "z": 1,
      "name": "Te_Whenua_Plant_Rimu_Leaves"
    },
    {
      "x": -3,
      "y": 28,
      "z": 1,
      "name": "Te_Whenua_Plant_Rimu_Leaves"
    },
    {
      "x": -3,
      "y": 29,
      "z": 1,
      "name": "Te_Whenua_Plant_Rimu_Leaves"
    },
    {
      "x": -3,
      "y": 30,
      "z": 1,
      "name": "Te_Whenua_Plant_Rimu_Leaves"
    },
    {
      "x": -3,
      "y": 18,
      "z": 2,
      "name": "Te_Whenua_Plant_Rimu_Leaves"
    },
    {
      "x": -3,
      "y": 19,
      "z": 2,
      "name": "Te_Whenua_Plant_Rimu_Leaves"
    },
    {
      "x": -3,
      "y": 20,
      "z": 2,
      "name": "Te_Whenua_Plant_Rimu_Leaves"
    },
    {
      "x": -3,
      "y": 21,
      "z": 2,
      "name": "Te_Whenua_Plant_Rimu_Leaves"
    },
    {
      "x": -3,
      "y": 22,
      "z": 2,
      "name": "Te_Whenua_Plant_Rimu_Leaves"
    },
    {
      "x": -3,
      "y": 23,
      "z": 2,
      "name": "Te_Whenua_Plant_Rimu_Leaves"
    },
    {
      "x": -3,
      "y": 24,
      "z": 2,
      "name": "Te_Whenua_Plant_Rimu_Leaves"
    },
    {
      "x": -3,
      "y": 25,
      "z": 2,
      "name": "Te_Whenua_Plant_Rimu_Leaves"
    },
    {
      "x": -3,
      "y": 26,
      "z": 2,
      "name": "Te_Whenua_Plant_Rimu_Leaves"
    },
    {
      "x": -3,
      "y": 27,
      "z": 2,
      "name": "Te_Whenua_Plant_Rimu_Leaves"
    },
    {
      "x": -3,
      "y": 28,
      "z": 2,
      "name": "Te_Whenua_Plant_Rimu_Leaves"
    },
    {
      "x": -3,
      "y": 29,
      "z": 2,
      "name": "Te_Whenua_Plant_Rimu_Leaves"
    },
    {
      "x": -3,
      "y": 23,
      "z": 3,
      "name": "Te_Whenua_Plant_Rimu_Leaves"
    },
    {
      "x": -3,
      "y": 24,
      "z": 3,
      "name": "Te_Whenua_Plant_Rimu_Leaves"
    },
    {
      "x": -3,
      "y": 25,
      "z": 3,
      "name": "Te_Whenua_Plant_Rimu_Leaves"
    },
    {
      "x": -2,
      "y": 19,
      "z": -3,
      "name": "Te_Whenua_Plant_Rimu_Leaves"
    },
    {
      "x": -2,
      "y": 20,
      "z": -3,
      "name": "Te_Whenua_Plant_Rimu_Leaves"
    },
    {
      "x": -2,
      "y": 21,
      "z": -3,
      "name": "Te_Whenua_Plant_Rimu_Leaves"
    },
    {
      "x": -2,
      "y": 16,
      "z": -2,
      "name": "Te_Whenua_Plant_Rimu_Leaves"
    },
    {
      "x": -2,
      "y": 17,
      "z": -2,
      "name": "Te_Whenua_Plant_Rimu_Leaves"
    },
    {
      "x": -2,
      "y": 18,
      "z": -2,
      "name": "Te_Whenua_Plant_Rimu_Leaves"
    },
    {
      "x": -2,
      "y": 19,
      "z": -2,
      "name": "Te_Whenua_Plant_Rimu_Leaves"
    },
    {
      "x": -2,
      "y": 20,
      "z": -2,
      "name": "Te_Whenua_Plant_Rimu_Leaves"
    },
    {
      "x": -2,
      "y": 21,
      "z": -2,
      "name": "Te_Whenua_Plant_Rimu_Leaves"
    },
    {
      "x": -2,
      "y": 22,
      "z": -2,
      "name": "Te_Whenua_Plant_Rimu_Leaves"
    },
    {
      "x": -2,
      "y": 16,
      "z": -1,
      "name": "Te_Whenua_Plant_Rimu_Leaves"
    },
    {
      "x": -2,
      "y": 17,
      "z": -1,
      "name": "Te_Whenua_Plant_Rimu_Leaves"
    },
    {
      "x": -2,
      "y": 18,
      "z": -1,
      "name": "Te_Whenua_Plant_Rimu_Leaves"
    },
    {
      "x": -2,
      "y": 19,
      "z": -1,
      "name": "Te_Whenua_Plant_Rimu_Leaves"
    },
    {
      "x": -2,
      "y": 20,
      "z": -1,
      "name": "Te_Whenua_Plant_Rimu_Leaves"
    },
    {
      "x": -2,
      "y": 21,
      "z": -1,
      "name": "Te_Whenua_Plant_Rimu_Leaves"
    },
    {
      "x": -2,
      "y": 22,
      "z": -1,
      "name": "Te_Whenua_Plant_Rimu_Leaves"
    },
    {
      "x": -2,
      "y": 23,
      "z": -1,
      "name": "Te_Whenua_Plant_Rimu_Leaves"
    },
    {
      "x": -2,
      "y": 24,
      "z": -1,
      "name": "Te_Whenua_Plant_Rimu_Leaves"
    },
    {
      "x": -2,
      "y": 25,
      "z": -1,
      "name": "Te_Whenua_Plant_Rimu_Leaves"
    },
    {
      "x": -2,
      "y": 26,
      "z": -1,
      "name": "Te_Whenua_Plant_Rimu_Leaves"
    },
    {
      "x": -2,
      "y": 16,
      "z": 0,
      "name": "Te_Whenua_Plant_Rimu_Leaves"
    },
    {
      "x": -2,
      "y": 17,
      "z": 0,
      "name": "Te_Whenua_Plant_Rimu_Leaves"
    },
    {
      "x": -2,
      "y": 18,
      "z": 0,
      "name": "Te_Whenua_Plant_Rimu_Leaves"
    },
    {
      "x": -2,
      "y": 19,
      "z": 0,
      "name": "Te_Whenua_Plant_Rimu_Leaves"
    },
    {
      "x": -2,
      "y": 20,
      "z": 0,
      "name": "Te_Whenua_Plant_Rimu_Leaves"
    },
    {
      "x": -2,
      "y": 21,
      "z": 0,
      "name": "Te_Whenua_Plant_Rimu_Leaves"
    },
    {
      "x": -2,
      "y": 22,
      "z": 0,
      "name": "Te_Whenua_Plant_Rimu_Leaves"
    },
    {
      "x": -2,
      "y": 23,
      "z": 0,
      "name": "Te_Whenua_Plant_Rimu_Leaves"
    },
    {
      "x": -2,
      "y": 24,
      "z": 0,
      "name": "Te_Whenua_Plant_Rimu_Leaves"
    },
    {
      "x": -2,
      "y": 25,
      "z": 0,
      "name": "Te_Whenua_Plant_Rimu_Leaves"
    },
    {
      "x": -2,
      "y": 26,
      "z": 0,
      "name": "Te_Whenua_Plant_Rimu_Leaves"
    },
    {
      "x": -2,
      "y": 27,
      "z": 0,
      "name": "Te_Whenua_Plant_Rimu_Leaves"
    },
    {
      "x": -2,
      "y": 28,
      "z": 0,
      "name": "Te_Whenua_Plant_Rimu_Leaves"
    },
    {
      "x": -2,
      "y": 29,
      "z": 0,
      "name": "Te_Whenua_Plant_Rimu_Leaves"
    },
    {
      "x": -2,
      "y": 15,
      "z": 1,
      "name": "Te_Whenua_Plant_Rimu_Leaves"
    },
    {
      "x": -2,
      "y": 16,
      "z": 1,
      "name": "Te_Whenua_Plant_Rimu_Leaves"
    },
    {
      "x": -2,
      "y": 17,
      "z": 1,
      "name": "Te_Whenua_Plant_Rimu_Leaves"
    },
    {
      "x": -2,
      "y": 18,
      "z": 1,
      "name": "Te_Whenua_Plant_Rimu_Leaves"
    },
    {
      "x": -2,
      "y": 19,
      "z": 1,
      "name": "Te_Whenua_Wood_Rimu_Branch_Long",
      "rotation": 5
    },
    {
      "x": -2,
      "y": 20,
      "z": 1,
      "name": "Te_Whenua_Plant_Rimu_Leaves"
    },
    {
      "x": -2,
      "y": 21,
      "z": 1,
      "name": "Te_Whenua_Plant_Rimu_Leaves"
    },
    {
      "x": -2,
      "y": 22,
      "z": 1,
      "name": "Te_Whenua_Plant_Rimu_Leaves"
    },
    {
      "x": -2,
      "y": 23,
      "z": 1,
      "name": "Te_Whenua_Plant_Rimu_Leaves"
    },
    {
      "x": -2,
      "y": 24,
      "z": 1,
      "name": "Te_Whenua_Plant_Rimu_Leaves"
    },
    {
      "x": -2,
      "y": 25,
      "z": 1,
      "name": "Te_Whenua_Plant_Rimu_Leaves"
    },
    {
      "x": -2,
      "y": 26,
      "z": 1,
      "name": "Te_Whenua_Plant_Rimu_Leaves"
    },
    {
      "x": -2,
      "y": 27,
      "z": 1,
      "name": "Te_Whenua_Plant_Rimu_Leaves"
    },
    {
      "x": -2,
      "y": 28,
      "z": 1,
      "name": "Te_Whenua_Plant_Rimu_Leaves"
    },
    {
      "x": -2,
      "y": 29,
      "z": 1,
      "name": "Te_Whenua_Plant_Rimu_Leaves"
    },
    {
      "x": -2,
      "y": 30,
      "z": 1,
      "name": "Te_Whenua_Plant_Rimu_Leaves"
    },
    {
      "x": -2,
      "y": 16,
      "z": 2,
      "name": "Te_Whenua_Plant_Rimu_Leaves"
    },
    {
      "x": -2,
      "y": 17,
      "z": 2,
      "name": "Te_Whenua_Plant_Rimu_Leaves"
    },
    {
      "x": -2,
      "y": 18,
      "z": 2,
      "name": "Te_Whenua_Plant_Rimu_Leaves"
    },
    {
      "x": -2,
      "y": 19,
      "z": 2,
      "name": "Te_Whenua_Plant_Rimu_Leaves"
    },
    {
      "x": -2,
      "y": 20,
      "z": 2,
      "name": "Te_Whenua_Plant_Rimu_Leaves"
    },
    {
      "x": -2,
      "y": 21,
      "z": 2,
      "name": "Te_Whenua_Plant_Rimu_Leaves"
    },
    {
      "x": -2,
      "y": 22,
      "z": 2,
      "name": "Te_Whenua_Plant_Rimu_Leaves"
    },
    {
      "x": -2,
      "y": 23,
      "z": 2,
      "name": "Te_Whenua_Plant_Rimu_Leaves"
    },
    {
      "x": -2,
      "y": 24,
      "z": 2,
      "name": "Te_Whenua_Wood_Rimu_Branch_Long",
      "rotation": 5
    },
    {
      "x": -2,
      "y": 25,
      "z": 2,
      "name": "Te_Whenua_Plant_Rimu_Leaves"
    },
    {
      "x": -2,
      "y": 26,
      "z": 2,
      "name": "Te_Whenua_Plant_Rimu_Leaves"
    },
    {
      "x": -2,
      "y": 27,
      "z": 2,
      "name": "Te_Whenua_Plant_Rimu_Leaves"
    },
    {
      "x": -2,
      "y": 28,
      "z": 2,
      "name": "Te_Whenua_Plant_Rimu_Leaves"
    },
    {
      "x": -2,
      "y": 29,
      "z": 2,
      "name": "Te_Whenua_Plant_Rimu_Leaves"
    },
    {
      "x": -2,
      "y": 21,
      "z": 3,
      "name": "Te_Whenua_Plant_Rimu_Leaves"
    },
    {
      "x": -2,
      "y": 22,
      "z": 3,
      "name": "Te_Whenua_Plant_Rimu_Leaves"
    },
    {
      "x": -2,
      "y": 23,
      "z": 3,
      "name": "Te_Whenua_Plant_Rimu_Leaves"
    },
    {
      "x": -2,
      "y": 24,
      "z": 3,
      "name": "Te_Whenua_Plant_Rimu_Leaves"
    },
    {
      "x": -2,
      "y": 25,
      "z": 3,
      "name": "Te_Whenua_Plant_Rimu_Leaves"
    },
    {
      "x": -2,
      "y": 30,
      "z": 3,
      "name": "Te_Whenua_Plant_Rimu_Leaves"
    },
    {
      "x": -2,
      "y": 31,
      "z": 3,
      "name": "Te_Whenua_Plant_Rimu_Leaves"
    },
    {
      "x": -2,
      "y": 32,
      "z": 3,
      "name": "Te_Whenua_Plant_Rimu_Leaves"
    },
    {
      "x": -1,
      "y": 16,
      "z": -3,
      "name": "Te_Whenua_Plant_Rimu_Leaves"
    },
    {
      "x": -1,
      "y": 17,
      "z": -3,
      "name": "Te_Whenua_Plant_Rimu_Leaves"
    },
    {
      "x": -1,
      "y": 18,
      "z": -3,
      "name": "Te_Whenua_Plant_Rimu_Leaves"
    },
    {
      "x": -1,
      "y": 15,
      "z": -2,
      "name": "Te_Whenua_Plant_Rimu_Leaves"
    },
    {
      "x": -1,
      "y": 16,
      "z": -2,
      "name": "Te_Whenua_Plant_Rimu_Leaves"
    },
    {
      "x": -1,
      "y": 17,
      "z": -2,
      "name": "Te_Whenua_Plant_Rimu_Leaves"
    },
    {
      "x": -1,
      "y": 18,
      "z": -2,
      "name": "Te_Whenua_Plant_Rimu_Leaves"
    },
    {
      "x": -1,
      "y": 19,
      "z": -2,
      "name": "Te_Whenua_Plant_Rimu_Leaves"
    },
    {
      "x": -1,
      "y": 20,
      "z": -2,
      "name": "Te_Whenua_Plant_Rimu_Leaves"
    },
    {
      "x": -1,
      "y": 21,
      "z": -2,
      "name": "Te_Whenua_Plant_Rimu_Leaves"
    },
    {
      "x": -1,
      "y": 22,
      "z": -2,
      "name": "Te_Whenua_Plant_Rimu_Leaves"
    },
    {
      "x": -1,
      "y": 23,
      "z": -2,
      "name": "Te_Whenua_Plant_Rimu_Leaves"
    },
    {
      "x": -1,
      "y": 24,
      "z": -2,
      "name": "Te_Whenua_Plant_Rimu_Leaves"
    },
    {
      "x": -1,
      "y": 25,
      "z": -2,
      "name": "Te_Whenua_Plant_Rimu_Leaves"
    },
    {
      "x": -1,
      "y": 26,
      "z": -2,
      "name": "Te_Whenua_Plant_Rimu_Leaves"
    },
    {
      "x": -1,
      "y": 29,
      "z": -2,
      "name": "Te_Whenua_Plant_Rimu_Leaves"
    },
    {
      "x": -1,
      "y": 30,
      "z": -2,
      "name": "Te_Whenua_Plant_Rimu_Leaves"
    },
    {
      "x": -1,
      "y": 31,
      "z": -2,
      "name": "Te_Whenua_Plant_Rimu_Leaves"
    },
    {
      "x": -1,
      "y": 15,
      "z": -1,
      "name": "Te_Whenua_Plant_Rimu_Leaves"
    },
    {
      "x": -1,
      "y": 16,
      "z": -1,
      "name": "Te_Whenua_Plant_Rimu_Leaves"
    },
    {
      "x": -1,
      "y": 17,
      "z": -1,
      "name": "Te_Whenua_Plant_Rimu_Leaves"
    },
    {
      "x": -1,
      "y": 18,
      "z": -1,
      "name": "Te_Whenua_Plant_Rimu_Leaves"
    },
    {
      "x": -1,
      "y": 19,
      "z": -1,
      "name": "Te_Whenua_Plant_Rimu_Leaves"
    },
    {
      "x": -1,
      "y": 20,
      "z": -1,
      "name": "Te_Whenua_Plant_Rimu_Leaves"
    },
    {
      "x": -1,
      "y": 21,
      "z": -1,
      "name": "Te_Whenua_Plant_Rimu_Leaves"
    },
    {
      "x": -1,
      "y": 22,
      "z": -1,
      "name": "Te_Whenua_Plant_Rimu_Leaves"
    },
    {
      "x": -1,
      "y": 23,
      "z": -1,
      "name": "Te_Whenua_Plant_Rimu_Leaves"
    },
    {
      "x": -1,
      "y": 24,
      "z": -1,
      "name": "Te_Whenua_Plant_Rimu_Leaves"
    },
    {
      "x": -1,
      "y": 25,
      "z": -1,
      "name": "Te_Whenua_Plant_Rimu_Leaves"
    },
    {
      "x": -1,
      "y": 26,
      "z": -1,
      "name": "Te_Whenua_Plant_Rimu_Leaves"
    },
    {
      "x": -1,
      "y": 27,
      "z": -1,
      "name": "Te_Whenua_Plant_Rimu_Leaves"
    },
    {
      "x": -1,
      "y": 28,
      "z": -1,
      "name": "Te_Whenua_Plant_Rimu_Leaves"
    },
    {
      "x": -1,
      "y": 29,
      "z": -1,
      "name": "Te_Whenua_Plant_Rimu_Leaves"
    },
    {
      "x": -1,
      "y": 30,
      "z": -1,
      "name": "Te_Whenua_Plant_Rimu_Leaves"
    },
    {
      "x": -1,
      "y": 16,
      "z": 0,
      "name": "Te_Whenua_Plant_Rimu_Leaves"
    },
    {
      "x": -1,
      "y": 17,
      "z": 0,
      "name": "Te_Whenua_Plant_Rimu_Leaves"
    },
    {
      "x": -1,
      "y": 18,
      "z": 0,
      "name": "Te_Whenua_Plant_Rimu_Leaves"
    },
    {
      "x": -1,
      "y": 19,
      "z": 0,
      "name": "Te_Whenua_Plant_Rimu_Leaves"
    },
    {
      "x": -1,
      "y": 20,
      "z": 0,
      "name": "Te_Whenua_Plant_Rimu_Leaves"
    },
    {
      "x": -1,
      "y": 21,
      "z": 0,
      "name": "Te_Whenua_Plant_Rimu_Leaves"
    },
    {
      "x": -1,
      "y": 22,
      "z": 0,
      "name": "Te_Whenua_Plant_Rimu_Leaves"
    },
    {
      "x": -1,
      "y": 23,
      "z": 0,
      "name": "Te_Whenua_Plant_Rimu_Leaves"
    },
    {
      "x": -1,
      "y": 24,
      "z": 0,
      "name": "Te_Whenua_Plant_Rimu_Leaves"
    },
    {
      "x": -1,
      "y": 25,
      "z": 0,
      "name": "Te_Whenua_Plant_Rimu_Leaves"
    },
    {
      "x": -1,
      "y": 26,
      "z": 0,
      "name": "Te_Whenua_Plant_Rimu_Leaves"
    },
    {
      "x": -1,
      "y": 27,
      "z": 0,
      "name": "Te_Whenua_Plant_Rimu_Leaves"
    },
    {
      "x": -1,
      "y": 28,
      "z": 0,
      "name": "Te_Whenua_Plant_Rimu_Leaves"
    },
    {
      "x": -1,
      "y": 29,
      "z": 0,
      "name": "Te_Whenua_Plant_Rimu_Leaves"
    },
    {
      "x": -1,
      "y": 30,
      "z": 0,
      "name": "Te_Whenua_Plant_Rimu_Leaves"
    },
    {
      "x": -1,
      "y": 31,
      "z": 0,
      "name": "Te_Whenua_Plant_Rimu_Leaves"
    },
    {
      "x": -1,
      "y": 0,
      "z": 1,
      "name": "Te_Whenua_Wood_Rimu_Trunk"
    },
    {
      "x": -1,
      "y": 1,
      "z": 1,
      "name": "Te_Whenua_Wood_Rimu_Trunk_Full"
    },
    {
      "x": -1,
      "y": 16,
      "z": 1,
      "name": "Te_Whenua_Plant_Rimu_Leaves"
    },
    {
      "x": -1,
      "y": 17,
      "z": 1,
      "name": "Te_Whenua_Plant_Rimu_Leaves"
    },
    {
      "x": -1,
      "y": 18,
      "z": 1,
      "name": "Te_Whenua_Plant_Rimu_Leaves"
    },
    {
      "x": -1,
      "y": 19,
      "z": 1,
      "name": "Te_Whenua_Wood_Rimu_Branch_Long",
      "rotation": 5
    },
    {
      "x": -1,
      "y": 20,
      "z": 1,
      "name": "Te_Whenua_Plant_Rimu_Leaves"
    },
    {
      "x": -1,
      "y": 21,
      "z": 1,
      "name": "Te_Whenua_Plant_Rimu_Leaves"
    },
    {
      "x": -1,
      "y": 22,
      "z": 1,
      "name": "Te_Whenua_Plant_Rimu_Leaves"
    },
    {
      "x": -1,
      "y": 23,
      "z": 1,
      "name": "Te_Whenua_Plant_Rimu_Leaves"
    },
    {
      "x": -1,
      "y": 24,
      "z": 1,
      "name": "Te_Whenua_Plant_Rimu_Leaves"
    },
    {
      "x": -1,
      "y": 25,
      "z": 1,
      "name": "Te_Whenua_Plant_Rimu_Leaves"
    },
    {
      "x": -1,
      "y": 26,
      "z": 1,
      "name": "Te_Whenua_Plant_Rimu_Leaves"
    },
    {
      "x": -1,
      "y": 27,
      "z": 1,
      "name": "Te_Whenua_Plant_Rimu_Leaves"
    },
    {
      "x": -1,
      "y": 28,
      "z": 1,
      "name": "Te_Whenua_Wood_Rimu_Branch_Long",
      "rotation": 5
    },
    {
      "x": -1,
      "y": 29,
      "z": 1,
      "name": "Te_Whenua_Plant_Rimu_Leaves"
    },
    {
      "x": -1,
      "y": 30,
      "z": 1,
      "name": "Te_Whenua_Plant_Rimu_Leaves"
    },
    {
      "x": -1,
      "y": 31,
      "z": 1,
      "name": "Te_Whenua_Plant_Rimu_Leaves"
    },
    {
      "x": -1,
      "y": 32,
      "z": 1,
      "name": "Te_Whenua_Plant_Rimu_Leaves"
    },
    {
      "x": -1,
      "y": 33,
      "z": 1,
      "name": "Te_Whenua_Plant_Rimu_Leaves"
    },
    {
      "x": -1,
      "y": 0,
      "z": 2,
      "name": "Te_Whenua_Wood_Rimu_Trunk_Full"
    },
    {
      "x": -1,
      "y": 17,
      "z": 2,
      "name": "Te_Whenua_Wood_Rimu_Branch_Short",
      "rotation": 3
    },
    {
      "x": -1,
      "y": 18,
      "z": 2,
      "name": "Te_Whenua_Plant_Rimu_Leaves"
    },
    {
      "x": -1,
      "y": 19,
      "z": 2,
      "name": "Te_Whenua_Plant_Rimu_Leaves"
    },
    {
      "x": -1,
      "y": 20,
      "z": 2,
      "name": "Te_Whenua_Plant_Rimu_Leaves"
    },
    {
      "x": -1,
      "y": 21,
      "z": 2,
      "name": "Te_Whenua_Plant_Rimu_Leaves"
    },
    {
      "x": -1,
      "y": 22,
      "z": 2,
      "name": "Te_Whenua_Plant_Rimu_Leaves"
    },
    {
      "x": -1,
      "y": 23,
      "z": 2,
      "name": "Te_Whenua_Plant_Rimu_Leaves"
    },
    {
      "x": -1,
      "y": 24,
      "z": 2,
      "name": "Te_Whenua_Wood_Rimu_Branch_Long",
      "rotation": 5
    },
    {
      "x": -1,
      "y": 25,
      "z": 2,
      "name": "Te_Whenua_Plant_Rimu_Leaves"
    },
    {
      "x": -1,
      "y": 26,
      "z": 2,
      "name": "Te_Whenua_Plant_Rimu_Leaves"
    },
    {
      "x": -1,
      "y": 27,
      "z": 2,
      "name": "Te_Whenua_Plant_Rimu_Leaves"
    },
    {
      "x": -1,
      "y": 28,
      "z": 2,
      "name": "Te_Whenua_Plant_Rimu_Leaves"
    },
    {
      "x": -1,
      "y": 29,
      "z": 2,
      "name": "Te_Whenua_Plant_Rimu_Leaves"
    },
    {
      "x": -1,
      "y": 30,
      "z": 2,
      "name": "Te_Whenua_Plant_Rimu_Leaves"
    },
    {
      "x": -1,
      "y": 31,
      "z": 2,
      "name": "Te_Whenua_Plant_Rimu_Leaves"
    },
    {
      "x": -1,
      "y": 32,
      "z": 2,
      "name": "Te_Whenua_Plant_Rimu_Leaves"
    },
    {
      "x": -1,
      "y": 18,
      "z": 3,
      "name": "Te_Whenua_Plant_Rimu_Leaves"
    },
    {
      "x": -1,
      "y": 19,
      "z": 3,
      "name": "Te_Whenua_Plant_Rimu_Leaves"
    },
    {
      "x": -1,
      "y": 20,
      "z": 3,
      "name": "Te_Whenua_Plant_Rimu_Leaves"
    },
    {
      "x": -1,
      "y": 23,
      "z": 3,
      "name": "Te_Whenua_Plant_Rimu_Leaves"
    },
    {
      "x": -1,
      "y": 24,
      "z": 3,
      "name": "Te_Whenua_Plant_Rimu_Leaves"
    },
    {
      "x": -1,
      "y": 25,
      "z": 3,
      "name": "Te_Whenua_Plant_Rimu_Leaves"
    },
    {
      "x": -1,
      "y": 26,
      "z": 3,
      "name": "Te_Whenua_Plant_Rimu_Leaves"
    },
    {
      "x": -1,
      "y": 27,
      "z": 3,
      "name": "Te_Whenua_Plant_Rimu_Leaves"
    },
    {
      "x": -1,
      "y": 28,
      "z": 3,
      "name": "Te_Whenua_Plant_Rimu_Leaves"
    },
    {
      "x": -1,
      "y": 29,
      "z": 3,
      "name": "Te_Whenua_Plant_Rimu_Leaves"
    },
    {
      "x": -1,
      "y": 30,
      "z": 3,
      "name": "Te_Whenua_Plant_Rimu_Leaves"
    },
    {
      "x": -1,
      "y": 31,
      "z": 3,
      "name": "Te_Whenua_Plant_Rimu_Leaves"
    },
    {
      "x": -1,
      "y": 32,
      "z": 3,
      "name": "Te_Whenua_Plant_Rimu_Leaves"
    },
    {
      "x": -1,
      "y": 33,
      "z": 3,
      "name": "Te_Whenua_Plant_Rimu_Leaves"
    },
    {
      "x": -1,
      "y": 30,
      "z": 4,
      "name": "Te_Whenua_Plant_Rimu_Leaves"
    },
    {
      "x": -1,
      "y": 31,
      "z": 4,
      "name": "Te_Whenua_Plant_Rimu_Leaves"
    },
    {
      "x": -1,
      "y": 32,
      "z": 4,
      "name": "Te_Whenua_Plant_Rimu_Leaves"
    },
    {
      "x": 0,
      "y": 20,
      "z": -4,
      "name": "Te_Whenua_Plant_Rimu_Leaves"
    },
    {
      "x": 0,
      "y": 21,
      "z": -4,
      "name": "Te_Whenua_Plant_Rimu_Leaves"
    },
    {
      "x": 0,
      "y": 22,
      "z": -4,
      "name": "Te_Whenua_Plant_Rimu_Leaves"
    },
    {
      "x": 0,
      "y": 20,
      "z": -3,
      "name": "Te_Whenua_Plant_Rimu_Leaves"
    },
    {
      "x": 0,
      "y": 21,
      "z": -3,
      "name": "Te_Whenua_Plant_Rimu_Leaves"
    },
    {
      "x": 0,
      "y": 22,
      "z": -3,
      "name": "Te_Whenua_Plant_Rimu_Leaves"
    },
    {
      "x": 0,
      "y": 24,
      "z": -3,
      "name": "Te_Whenua_Plant_Rimu_Leaves"
    },
    {
      "x": 0,
      "y": 25,
      "z": -3,
      "name": "Te_Whenua_Plant_Rimu_Leaves"
    },
    {
      "x": 0,
      "y": 26,
      "z": -3,
      "name": "Te_Whenua_Plant_Rimu_Leaves"
    },
    {
      "x": 0,
      "y": 29,
      "z": -3,
      "name": "Te_Whenua_Plant_Rimu_Leaves"
    },
    {
      "x": 0,
      "y": 30,
      "z": -3,
      "name": "Te_Whenua_Plant_Rimu_Leaves"
    },
    {
      "x": 0,
      "y": 31,
      "z": -3,
      "name": "Te_Whenua_Plant_Rimu_Leaves"
    },
    {
      "x": 0,
      "y": 16,
      "z": -2,
      "name": "Te_Whenua_Plant_Rimu_Leaves"
    },
    {
      "x": 0,
      "y": 17,
      "z": -2,
      "name": "Te_Whenua_Plant_Rimu_Leaves"
    },
    {
      "x": 0,
      "y": 18,
      "z": -2,
      "name": "Te_Whenua_Plant_Rimu_Leaves"
    },
    {
      "x": 0,
      "y": 21,
      "z": -2,
      "name": "Te_Whenua_Plant_Rimu_Leaves"
    },
    {
      "x": 0,
      "y": 22,
      "z": -2,
      "name": "Te_Whenua_Plant_Rimu_Leaves"
    },
    {
      "x": 0,
      "y": 23,
      "z": -2,
      "name": "Te_Whenua_Plant_Rimu_Leaves"
    },
    {
      "x": 0,
      "y": 24,
      "z": -2,
      "name": "Te_Whenua_Plant_Rimu_Leaves"
    },
    {
      "x": 0,
      "y": 25,
      "z": -2,
      "name": "Te_Whenua_Plant_Rimu_Leaves"
    },
    {
      "x": 0,
      "y": 26,
      "z": -2,
      "name": "Te_Whenua_Plant_Rimu_Leaves"
    },
    {
      "x": 0,
      "y": 27,
      "z": -2,
      "name": "Te_Whenua_Plant_Rimu_Leaves"
    },
    {
      "x": 0,
      "y": 28,
      "z": -2,
      "name": "Te_Whenua_Plant_Rimu_Leaves"
    },
    {
      "x": 0,
      "y": 29,
      "z": -2,
      "name": "Te_Whenua_Plant_Rimu_Leaves"
    },
    {
      "x": 0,
      "y": 30,
      "z": -2,
      "name": "Te_Whenua_Plant_Rimu_Leaves"
    },
    {
      "x": 0,
      "y": 31,
      "z": -2,
      "name": "Te_Whenua_Plant_Rimu_Leaves"
    },
    {
      "x": 0,
      "y": 32,
      "z": -2,
      "name": "Te_Whenua_Plant_Rimu_Leaves"
    },
    {
      "x": 0,
      "y": 16,
      "z": -1,
      "name": "Te_Whenua_Plant_Rimu_Leaves"
    },
    {
      "x": 0,
      "y": 17,
      "z": -1,
      "name": "Te_Whenua_Plant_Rimu_Leaves"
    },
    {
      "x": 0,
      "y": 18,
      "z": -1,
      "name": "Te_Whenua_Plant_Rimu_Leaves"
    },
    {
      "x": 0,
      "y": 19,
      "z": -1,
      "name": "Te_Whenua_Plant_Rimu_Leaves"
    },
    {
      "x": 0,
      "y": 20,
      "z": -1,
      "name": "Te_Whenua_Plant_Rimu_Leaves"
    },
    {
      "x": 0,
      "y": 21,
      "z": -1,
      "name": "Te_Whenua_Plant_Rimu_Leaves"
    },
    {
      "x": 0,
      "y": 22,
      "z": -1,
      "name": "Te_Whenua_Plant_Rimu_Leaves"
    },
    {
      "x": 0,
      "y": 23,
      "z": -1,
      "name": "Te_Whenua_Plant_Rimu_Leaves"
    },
    {
      "x": 0,
      "y": 24,
      "z": -1,
      "name": "Te_Whenua_Plant_Rimu_Leaves"
    },
    {
      "x": 0,
      "y": 25,
      "z": -1,
      "name": "Te_Whenua_Plant_Rimu_Leaves"
    },
    {
      "x": 0,
      "y": 26,
      "z": -1,
      "name": "Te_Whenua_Wood_Rimu_Branch_Long",
      "rotation": 4
    },
    {
      "x": 0,
      "y": 27,
      "z": -1,
      "name": "Te_Whenua_Plant_Rimu_Leaves"
    },
    {
      "x": 0,
      "y": 28,
      "z": -1,
      "name": "Te_Whenua_Plant_Rimu_Leaves"
    },
    {
      "x": 0,
      "y": 29,
      "z": -1,
      "name": "Te_Whenua_Plant_Rimu_Leaves"
    },
    {
      "x": 0,
      "y": 30,
      "z": -1,
      "name": "Te_Whenua_Wood_Rimu_Branch_Long",
      "rotation": 4
    },
    {
      "x": 0,
      "y": 31,
      "z": -1,
      "name": "Te_Whenua_Plant_Rimu_Leaves"
    },
    {
      "x": 0,
      "y": 0,
      "z": 0,
      "name": "Te_Whenua_Wood_Rimu_Trunk"
    },
    {
      "x": 0,
      "y": 1,
      "z": 0,
      "name": "Te_Whenua_Wood_Rimu_Trunk"
    },
    {
      "x": 0,
      "y": 2,
      "z": 0,
      "name": "Te_Whenua_Wood_Rimu_Trunk_Full"
    },
    {
      "x": 0,
      "y": 15,
      "z": 0,
      "name": "Te_Whenua_Plant_Rimu_Leaves"
    },
    {
      "x": 0,
      "y": 16,
      "z": 0,
      "name": "Te_Whenua_Plant_Rimu_Leaves"
    },
    {
      "x": 0,
      "y": 17,
      "z": 0,
      "name": "Te_Whenua_Plant_Rimu_Leaves"
    },
    {
      "x": 0,
      "y": 18,
      "z": 0,
      "name": "Te_Whenua_Plant_Rimu_Leaves"
    },
    {
      "x": 0,
      "y": 19,
      "z": 0,
      "name": "Te_Whenua_Plant_Rimu_Leaves"
    },
    {
      "x": 0,
      "y": 20,
      "z": 0,
      "name": "Te_Whenua_Plant_Rimu_Leaves"
    },
    {
      "x": 0,
      "y": 21,
      "z": 0,
      "name": "Te_Whenua_Plant_Rimu_Leaves"
    },
    {
      "x": 0,
      "y": 22,
      "z": 0,
      "name": "Te_Whenua_Plant_Rimu_Leaves"
    },
    {
      "x": 0,
      "y": 23,
      "z": 0,
      "name": "Te_Whenua_Plant_Rimu_Leaves"
    },
    {
      "x": 0,
      "y": 24,
      "z": 0,
      "name": "Te_Whenua_Plant_Rimu_Leaves"
    },
    {
      "x": 0,
      "y": 25,
      "z": 0,
      "name": "Te_Whenua_Plant_Rimu_Leaves"
    },
    {
      "x": 0,
      "y": 26,
      "z": 0,
      "name": "Te_Whenua_Wood_Rimu_Branch_Long",
      "rotation": 4
    },
    {
      "x": 0,
      "y": 27,
      "z": 0,
      "name": "Te_Whenua_Plant_Rimu_Leaves"
    },
    {
      "x": 0,
      "y": 28,
      "z": 0,
      "name": "Te_Whenua_Plant_Rimu_Leaves"
    },
    {
      "x": 0,
      "y": 29,
      "z": 0,
      "name": "Te_Whenua_Plant_Rimu_Leaves"
    },
    {
      "x": 0,
      "y": 30,
      "z": 0,
      "name": "Te_Whenua_Wood_Rimu_Branch_Long",
      "rotation": 4
    },
    {
      "x": 0,
      "y": 31,
      "z": 0,
      "name": "Te_Whenua_Plant_Rimu_Leaves"
    },
    {
      "x": 0,
      "y": 32,
      "z": 0,
      "name": "Te_Whenua_Plant_Rimu_Leaves"
    },
    {
      "x": 0,
      "y": 33,
      "z": 0,
      "name": "Te_Whenua_Plant_Rimu_Leaves"
    },
    {
      "x": 0,
      "y": 0,
      "z": 1,
      "name": "Te_Whenua_Wood_Rimu_Trunk"
    },
    {
      "x": 0,
      "y": 1,
      "z": 1,
      "name": "Te_Whenua_Wood_Rimu_Trunk"
    },
    {
      "x": 0,
      "y": 2,
      "z": 1,
      "name": "Te_Whenua_Wood_Rimu_Trunk"
    },
    {
      "x": 0,
      "y": 3,
      "z": 1,
      "name": "Te_Whenua_Wood_Rimu_Trunk"
    },
    {
      "x": 0,
      "y": 4,
      "z": 1,
      "name": "Te_Whenua_Wood_Rimu_Trunk"
    },
    {
      "x": 0,
      "y": 5,
      "z": 1,
      "name": "Te_Whenua_Wood_Rimu_Trunk"
    },
    {
      "x": 0,
      "y": 6,
      "z": 1,
      "name": "Te_Whenua_Wood_Rimu_Trunk"
    },
    {
      "x": 0,
      "y": 7,
      "z": 1,
      "name": "Te_Whenua_Wood_Rimu_Trunk"
    },
    {
      "x": 0,
      "y": 8,
      "z": 1,
      "name": "Te_Whenua_Wood_Rimu_Trunk"
    },
    {
      "x": 0,
      "y": 9,
      "z": 1,
      "name": "Te_Whenua_Wood_Rimu_Trunk"
    },
    {
      "x": 0,
      "y": 10,
      "z": 1,
      "name": "Te_Whenua_Wood_Rimu_Trunk"
    },
    {
      "x": 0,
      "y": 11,
      "z": 1,
      "name": "Te_Whenua_Wood_Rimu_Trunk"
    },
    {
      "x": 0,
      "y": 12,
      "z": 1,
      "name": "Te_Whenua_Wood_Rimu_Trunk"
    },
    {
      "x": 0,
      "y": 13,
      "z": 1,
      "name": "Te_Whenua_Wood_Rimu_Trunk"
    },
    {
      "x": 0,
      "y": 14,
      "z": 1,
      "name": "Te_Whenua_Wood_Rimu_Trunk"
    },
    {
      "x": 0,
      "y": 15,
      "z": 1,
      "name": "Te_Whenua_Wood_Rimu_Trunk"
    },
    {
      "x": 0,
      "y": 16,
      "z": 1,
      "name": "Te_Whenua_Wood_Rimu_Trunk"
    },
    {
      "x": 0,
      "y": 17,
      "z": 1,
      "name": "Te_Whenua_Wood_Rimu_Trunk"
    },
    {
      "x": 0,
      "y": 18,
      "z": 1,
      "name": "Te_Whenua_Wood_Rimu_Trunk"
    },
    {
      "x": 0,
      "y": 19,
      "z": 1,
      "name": "Te_Whenua_Wood_Rimu_Trunk"
    },
    {
      "x": 0,
      "y": 20,
      "z": 1,
      "name": "Te_Whenua_Wood_Rimu_Trunk"
    },
    {
      "x": 0,
      "y": 21,
      "z": 1,
      "name": "Te_Whenua_Wood_Rimu_Trunk"
    },
    {
      "x": 0,
      "y": 22,
      "z": 1,
      "name": "Te_Whenua_Wood_Rimu_Trunk"
    },
    {
      "x": 0,
      "y": 23,
      "z": 1,
      "name": "Te_Whenua_Wood_Rimu_Trunk"
    },
    {
      "x": 0,
      "y": 24,
      "z": 1,
      "name": "Te_Whenua_Wood_Rimu_Trunk"
    },
    {
      "x": 0,
      "y": 25,
      "z": 1,
      "name": "Te_Whenua_Wood_Rimu_Trunk"
    },
    {
      "x": 0,
      "y": 26,
      "z": 1,
      "name": "Te_Whenua_Wood_Rimu_Trunk"
    },
    {
      "x": 0,
      "y": 27,
      "z": 1,
      "name": "Te_Whenua_Wood_Rimu_Trunk"
    },
    {
      "x": 0,
      "y": 28,
      "z": 1,
      "name": "Te_Whenua_Wood_Rimu_Trunk"
    },
    {
      "x": 0,
      "y": 29,
      "z": 1,
      "name": "Te_Whenua_Wood_Rimu_Trunk"
    },
    {
      "x": 0,
      "y": 30,
      "z": 1,
      "name": "Te_Whenua_Wood_Rimu_Trunk_Full"
    },
    {
      "x": 0,
      "y": 31,
      "z": 1,
      "name": "Te_Whenua_Wood_Rimu_Branch_Long"
    },
    {
      "x": 0,
      "y": 32,
      "z": 1,
      "name": "Te_Whenua_Wood_Rimu_Branch_Long"
    },
    {
      "x": 0,
      "y": 33,
      "z": 1,
      "name": "Te_Whenua_Plant_Rimu_Leaves"
    },
    {
      "x": 0,
      "y": 34,
      "z": 1,
      "name": "Te_Whenua_Plant_Rimu_Leaves"
    },
    {
      "x": 0,
      "y": 0,
      "z": 2,
      "name": "Te_Whenua_Wood_Rimu_Trunk"
    },
    {
      "x": 0,
      "y": 1,
      "z": 2,
      "name": "Te_Whenua_Wood_Rimu_Trunk"
    },
    {
      "x": 0,
      "y": 2,
      "z": 2,
      "name": "Te_Whenua_Wood_Rimu_Trunk"
    },
    {
      "x": 0,
      "y": 3,
      "z": 2,
      "name": "Te_Whenua_Wood_Rimu_Trunk"
    },
    {
      "x": 0,
      "y": 4,
      "z": 2,
      "name": "Te_Whenua_Wood_Rimu_Trunk"
    },
    {
      "x": 0,
      "y": 5,
      "z": 2,
      "name": "Te_Whenua_Wood_Rimu_Trunk"
    },
    {
      "x": 0,
      "y": 6,
      "z": 2,
      "name": "Te_Whenua_Wood_Rimu_Trunk"
    },
    {
      "x": 0,
      "y": 7,
      "z": 2,
      "name": "Te_Whenua_Wood_Rimu_Trunk"
    },
    {
      "x": 0,
      "y": 8,
      "z": 2,
      "name": "Te_Whenua_Wood_Rimu_Trunk"
    },
    {
      "x": 0,
      "y": 9,
      "z": 2,
      "name": "Te_Whenua_Wood_Rimu_Trunk"
    },
    {
      "x": 0,
      "y": 10,
      "z": 2,
      "name": "Te_Whenua_Wood_Rimu_Trunk"
    },
    {
      "x": 0,
      "y": 11,
      "z": 2,
      "name": "Te_Whenua_Wood_Rimu_Trunk"
    },
    {
      "x": 0,
      "y": 12,
      "z": 2,
      "name": "Te_Whenua_Wood_Rimu_Trunk"
    },
    {
      "x": 0,
      "y": 13,
      "z": 2,
      "name": "Te_Whenua_Wood_Rimu_Trunk"
    },
    {
      "x": 0,
      "y": 14,
      "z": 2,
      "name": "Te_Whenua_Wood_Rimu_Trunk"
    },
    {
      "x": 0,
      "y": 15,
      "z": 2,
      "name": "Te_Whenua_Wood_Rimu_Trunk"
    },
    {
      "x": 0,
      "y": 16,
      "z": 2,
      "name": "Te_Whenua_Wood_Rimu_Trunk"
    },
    {
      "x": 0,
      "y": 17,
      "z": 2,
      "name": "Te_Whenua_Wood_Rimu_Trunk"
    },
    {
      "x": 0,
      "y": 18,
      "z": 2,
      "name": "Te_Whenua_Wood_Rimu_Trunk"
    },
    {
      "x": 0,
      "y": 19,
      "z": 2,
      "name": "Te_Whenua_Wood_Rimu_Trunk"
    },
    {
      "x": 0,
      "y": 20,
      "z": 2,
      "name": "Te_Whenua_Wood_Rimu_Trunk"
    },
    {
      "x": 0,
      "y": 21,
      "z": 2,
      "name": "Te_Whenua_Wood_Rimu_Trunk"
    },
    {
      "x": 0,
      "y": 22,
      "z": 2,
      "name": "Te_Whenua_Wood_Rimu_Trunk"
    },
    {
      "x": 0,
      "y": 23,
      "z": 2,
      "name": "Te_Whenua_Wood_Rimu_Trunk"
    },
    {
      "x": 0,
      "y": 24,
      "z": 2,
      "name": "Te_Whenua_Wood_Rimu_Trunk"
    },
    {
      "x": 0,
      "y": 25,
      "z": 2,
      "name": "Te_Whenua_Wood_Rimu_Trunk"
    },
    {
      "x": 0,
      "y": 26,
      "z": 2,
      "name": "Te_Whenua_Wood_Rimu_Trunk"
    },
    {
      "x": 0,
      "y": 27,
      "z": 2,
      "name": "Te_Whenua_Wood_Rimu_Trunk"
    },
    {
      "x": 0,
      "y": 28,
      "z": 2,
      "name": "Te_Whenua_Wood_Rimu_Trunk"
    },
    {
      "x": 0,
      "y": 29,
      "z": 2,
      "name": "Te_Whenua_Wood_Rimu_Trunk"
    },
    {
      "x": 0,
      "y": 30,
      "z": 2,
      "name": "Te_Whenua_Wood_Rimu_Trunk_Full"
    },
    {
      "x": 0,
      "y": 31,
      "z": 2,
      "name": "Te_Whenua_Plant_Rimu_Leaves"
    },
    {
      "x": 0,
      "y": 32,
      "z": 2,
      "name": "Te_Whenua_Plant_Rimu_Leaves"
    },
    {
      "x": 0,
      "y": 33,
      "z": 2,
      "name": "Te_Whenua_Plant_Rimu_Leaves"
    },
    {
      "x": 0,
      "y": 0,
      "z": 3,
      "name": "Te_Whenua_Wood_Rimu_Trunk_Full"
    },
    {
      "x": 0,
      "y": 14,
      "z": 3,
      "name": "Te_Whenua_Wood_Rimu_Branch_Short"
    },
    {
      "x": 0,
      "y": 16,
      "z": 3,
      "name": "Te_Whenua_Plant_Rimu_Leaves"
    },
    {
      "x": 0,
      "y": 17,
      "z": 3,
      "name": "Te_Whenua_Plant_Rimu_Leaves"
    },
    {
      "x": 0,
      "y": 18,
      "z": 3,
      "name": "Te_Whenua_Plant_Rimu_Leaves"
    },
    {
      "x": 0,
      "y": 19,
      "z": 3,
      "name": "Te_Whenua_Plant_Rimu_Leaves"
    },
    {
      "x": 0,
      "y": 20,
      "z": 3,
      "name": "Te_Whenua_Plant_Rimu_Leaves"
    },
    {
      "x": 0,
      "y": 23,
      "z": 3,
      "name": "Te_Whenua_Wood_Rimu_Branch_Short"
    },
    {
      "x": 0,
      "y": 26,
      "z": 3,
      "name": "Te_Whenua_Plant_Rimu_Leaves"
    },
    {
      "x": 0,
      "y": 27,
      "z": 3,
      "name": "Te_Whenua_Plant_Rimu_Leaves"
    },
    {
      "x": 0,
      "y": 28,
      "z": 3,
      "name": "Te_Whenua_Plant_Rimu_Leaves"
    },
    {
      "x": 0,
      "y": 29,
      "z": 3,
      "name": "Te_Whenua_Plant_Rimu_Leaves"
    },
    {
      "x": 0,
      "y": 30,
      "z": 3,
      "name": "Te_Whenua_Plant_Rimu_Leaves"
    },
    {
      "x": 0,
      "y": 31,
      "z": 3,
      "name": "Te_Whenua_Plant_Rimu_Leaves"
    },
    {
      "x": 0,
      "y": 32,
      "z": 3,
      "name": "Te_Whenua_Plant_Rimu_Leaves"
    },
    {
      "x": 0,
      "y": 18,
      "z": 4,
      "name": "Te_Whenua_Plant_Rimu_Leaves"
    },
    {
      "x": 0,
      "y": 19,
      "z": 4,
      "name": "Te_Whenua_Plant_Rimu_Leaves"
    },
    {
      "x": 0,
      "y": 20,
      "z": 4,
      "name": "Te_Whenua_Plant_Rimu_Leaves"
    },
    {
      "x": 0,
      "y": 27,
      "z": 4,
      "name": "Te_Whenua_Plant_Rimu_Leaves"
    },
    {
      "x": 0,
      "y": 28,
      "z": 4,
      "name": "Te_Whenua_Plant_Rimu_Leaves"
    },
    {
      "x": 0,
      "y": 29,
      "z": 4,
      "name": "Te_Whenua_Plant_Rimu_Leaves"
    },
    {
      "x": 0,
      "y": 30,
      "z": 4,
      "name": "Te_Whenua_Plant_Rimu_Leaves"
    },
    {
      "x": 0,
      "y": 31,
      "z": 4,
      "name": "Te_Whenua_Plant_Rimu_Leaves"
    },
    {
      "x": 1,
      "y": 20,
      "z": -5,
      "name": "Te_Whenua_Plant_Rimu_Leaves"
    },
    {
      "x": 1,
      "y": 21,
      "z": -5,
      "name": "Te_Whenua_Plant_Rimu_Leaves"
    },
    {
      "x": 1,
      "y": 22,
      "z": -5,
      "name": "Te_Whenua_Plant_Rimu_Leaves"
    },
    {
      "x": 1,
      "y": 19,
      "z": -4,
      "name": "Te_Whenua_Plant_Rimu_Leaves"
    },
    {
      "x": 1,
      "y": 20,
      "z": -4,
      "name": "Te_Whenua_Plant_Rimu_Leaves"
    },
    {
      "x": 1,
      "y": 21,
      "z": -4,
      "name": "Te_Whenua_Plant_Rimu_Leaves"
    },
    {
      "x": 1,
      "y": 22,
      "z": -4,
      "name": "Te_Whenua_Plant_Rimu_Leaves"
    },
    {
      "x": 1,
      "y": 23,
      "z": -4,
      "name": "Te_Whenua_Plant_Rimu_Leaves"
    },
    {
      "x": 1,
      "y": 19,
      "z": -3,
      "name": "Te_Whenua_Plant_Rimu_Leaves"
    },
    {
      "x": 1,
      "y": 20,
      "z": -3,
      "name": "Te_Whenua_Plant_Rimu_Leaves"
    },
    {
      "x": 1,
      "y": 21,
      "z": -3,
      "name": "Te_Whenua_Wood_Rimu_Branch_Long",
      "rotation": 4
    },
    {
      "x": 1,
      "y": 22,
      "z": -3,
      "name": "Te_Whenua_Plant_Rimu_Leaves"
    },
    {
      "x": 1,
      "y": 23,
      "z": -3,
      "name": "Te_Whenua_Plant_Rimu_Leaves"
    },
    {
      "x": 1,
      "y": 16,
      "z": -2,
      "name": "Te_Whenua_Plant_Rimu_Leaves"
    },
    {
      "x": 1,
      "y": 17,
      "z": -2,
      "name": "Te_Whenua_Plant_Rimu_Leaves"
    },
    {
      "x": 1,
      "y": 18,
      "z": -2,
      "name": "Te_Whenua_Plant_Rimu_Leaves"
    },
    {
      "x": 1,
      "y": 19,
      "z": -2,
      "name": "Te_Whenua_Plant_Rimu_Leaves"
    },
    {
      "x": 1,
      "y": 20,
      "z": -2,
      "name": "Te_Whenua_Plant_Rimu_Leaves"
    },
    {
      "x": 1,
      "y": 21,
      "z": -2,
      "name": "Te_Whenua_Wood_Rimu_Branch_Long",
      "rotation": 4
    },
    {
      "x": 1,
      "y": 22,
      "z": -2,
      "name": "Te_Whenua_Plant_Rimu_Leaves"
    },
    {
      "x": 1,
      "y": 23,
      "z": -2,
      "name": "Te_Whenua_Plant_Rimu_Leaves"
    },
    {
      "x": 1,
      "y": 24,
      "z": -2,
      "name": "Te_Whenua_Plant_Rimu_Leaves"
    },
    {
      "x": 1,
      "y": 25,
      "z": -2,
      "name": "Te_Whenua_Plant_Rimu_Leaves"
    },
    {
      "x": 1,
      "y": 26,
      "z": -2,
      "name": "Te_Whenua_Plant_Rimu_Leaves"
    },
    {
      "x": 1,
      "y": 29,
      "z": -2,
      "name": "Te_Whenua_Plant_Rimu_Leaves"
    },
    {
      "x": 1,
      "y": 30,
      "z": -2,
      "name": "Te_Whenua_Plant_Rimu_Leaves"
    },
    {
      "x": 1,
      "y": 31,
      "z": -2,
      "name": "Te_Whenua_Plant_Rimu_Leaves"
    },
    {
      "x": 1,
      "y": 15,
      "z": -1,
      "name": "Te_Whenua_Plant_Rimu_Leaves"
    },
    {
      "x": 1,
      "y": 16,
      "z": -1,
      "name": "Te_Whenua_Plant_Rimu_Leaves"
    },
    {
      "x": 1,
      "y": 17,
      "z": -1,
      "name": "Te_Whenua_Plant_Rimu_Leaves"
    },
    {
      "x": 1,
      "y": 18,
      "z": -1,
      "name": "Te_Whenua_Plant_Rimu_Leaves"
    },
    {
      "x": 1,
      "y": 19,
      "z": -1,
      "name": "Te_Whenua_Wood_Rimu_Branch_Corner",
      "rotation": 2
    },
    {
      "x": 1,
      "y": 20,
      "z": -1,
      "name": "Te_Whenua_Wood_Rimu_Branch_Long"
    },
    {
      "x": 1,
      "y": 21,
      "z": -1,
      "name": "Te_Whenua_Wood_Rimu_Branch_Corner",
      "rotation": 10
    },
    {
      "x": 1,
      "y": 22,
      "z": -1,
      "name": "Te_Whenua_Plant_Rimu_Leaves"
    },
    {
      "x": 1,
      "y": 23,
      "z": -1,
      "name": "Te_Whenua_Plant_Rimu_Leaves"
    },
    {
      "x": 1,
      "y": 25,
      "z": -1,
      "name": "Te_Whenua_Plant_Rimu_Leaves"
    },
    {
      "x": 1,
      "y": 26,
      "z": -1,
      "name": "Te_Whenua_Plant_Rimu_Leaves"
    },
    {
      "x": 1,
      "y": 27,
      "z": -1,
      "name": "Te_Whenua_Plant_Rimu_Leaves"
    },
    {
      "x": 1,
      "y": 28,
      "z": -1,
      "name": "Te_Whenua_Plant_Rimu_Leaves"
    },
    {
      "x": 1,
      "y": 29,
      "z": -1,
      "name": "Te_Whenua_Plant_Rimu_Leaves"
    },
    {
      "x": 1,
      "y": 30,
      "z": -1,
      "name": "Te_Whenua_Plant_Rimu_Leaves"
    },
    {
      "x": 1,
      "y": 0,
      "z": 0,
      "name": "Te_Whenua_Wood_Rimu_Trunk"
    },
    {
      "x": 1,
      "y": 1,
      "z": 0,
      "name": "Te_Whenua_Wood_Rimu_Trunk"
    },
    {
      "x": 1,
      "y": 2,
      "z": 0,
      "name": "Te_Whenua_Wood_Rimu_Trunk"
    },
    {
      "x": 1,
      "y": 3,
      "z": 0,
      "name": "Te_Whenua_Wood_Rimu_Trunk_Full"
    },
    {
      "x": 1,
      "y": 14,
      "z": 0,
      "name": "Te_Whenua_Plant_Rimu_Leaves"
    },
    {
      "x": 1,
      "y": 15,
      "z": 0,
      "name": "Te_Whenua_Wood_Rimu_Branch_Long",
      "rotation": 4
    },
    {
      "x": 1,
      "y": 16,
      "z": 0,
      "name": "Te_Whenua_Plant_Rimu_Leaves"
    },
    {
      "x": 1,
      "y": 17,
      "z": 0,
      "name": "Te_Whenua_Plant_Rimu_Leaves"
    },
    {
      "x": 1,
      "y": 18,
      "z": 0,
      "name": "Te_Whenua_Wood_Rimu_Branch_Corner",
      "rotation": 2
    },
    {
      "x": 1,
      "y": 19,
      "z": 0,
      "name": "Te_Whenua_Wood_Rimu_Branch_Corner",
      "rotation": 10
    },
    {
      "x": 1,
      "y": 20,
      "z": 0,
      "name": "Te_Whenua_Plant_Rimu_Leaves"
    },
    {
      "x": 1,
      "y": 21,
      "z": 0,
      "name": "Te_Whenua_Plant_Rimu_Leaves"
    },
    {
      "x": 1,
      "y": 22,
      "z": 0,
      "name": "Te_Whenua_Plant_Rimu_Leaves"
    },
    {
      "x": 1,
      "y": 23,
      "z": 0,
      "name": "Te_Whenua_Plant_Rimu_Leaves"
    },
    {
      "x": 1,
      "y": 24,
      "z": 0,
      "name": "Te_Whenua_Plant_Rimu_Leaves"
    },
    {
      "x": 1,
      "y": 25,
      "z": 0,
      "name": "Te_Whenua_Plant_Rimu_Leaves"
    },
    {
      "x": 1,
      "y": 26,
      "z": 0,
      "name": "Te_Whenua_Plant_Rimu_Leaves"
    },
    {
      "x": 1,
      "y": 27,
      "z": 0,
      "name": "Te_Whenua_Plant_Rimu_Leaves"
    },
    {
      "x": 1,
      "y": 28,
      "z": 0,
      "name": "Te_Whenua_Plant_Rimu_Leaves"
    },
    {
      "x": 1,
      "y": 29,
      "z": 0,
      "name": "Te_Whenua_Plant_Rimu_Leaves"
    },
    {
      "x": 1,
      "y": 30,
      "z": 0,
      "name": "Te_Whenua_Plant_Rimu_Leaves"
    },
    {
      "x": 1,
      "y": 31,
      "z": 0,
      "name": "Te_Whenua_Plant_Rimu_Leaves"
    },
    {
      "x": 1,
      "y": 32,
      "z": 0,
      "name": "Te_Whenua_Plant_Rimu_Leaves"
    },
    {
      "x": 1,
      "y": 0,
      "z": 1,
      "name": "Te_Whenua_Wood_Rimu_Trunk"
    },
    {
      "x": 1,
      "y": 1,
      "z": 1,
      "name": "Te_Whenua_Wood_Rimu_Trunk"
    },
    {
      "x": 1,
      "y": 2,
      "z": 1,
      "name": "Te_Whenua_Wood_Rimu_Trunk"
    },
    {
      "x": 1,
      "y": 3,
      "z": 1,
      "name": "Te_Whenua_Wood_Rimu_Trunk"
    },
    {
      "x": 1,
      "y": 4,
      "z": 1,
      "name": "Te_Whenua_Wood_Rimu_Trunk"
    },
    {
      "x": 1,
      "y": 5,
      "z": 1,
      "name": "Te_Whenua_Wood_Rimu_Trunk"
    },
    {
      "x": 1,
      "y": 6,
      "z": 1,
      "name": "Te_Whenua_Wood_Rimu_Trunk"
    },
    {
      "x": 1,
      "y": 7,
      "z": 1,
      "name": "Te_Whenua_Wood_Rimu_Trunk"
    },
    {
      "x": 1,
      "y": 8,
      "z": 1,
      "name": "Te_Whenua_Wood_Rimu_Trunk"
    },
    {
      "x": 1,
      "y": 9,
      "z": 1,
      "name": "Te_Whenua_Wood_Rimu_Trunk"
    },
    {
      "x": 1,
      "y": 10,
      "z": 1,
      "name": "Te_Whenua_Wood_Rimu_Trunk"
    },
    {
      "x": 1,
      "y": 11,
      "z": 1,
      "name": "Te_Whenua_Wood_Rimu_Trunk"
    },
    {
      "x": 1,
      "y": 12,
      "z": 1,
      "name": "Te_Whenua_Wood_Rimu_Trunk"
    },
    {
      "x": 1,
      "y": 13,
      "z": 1,
      "name": "Te_Whenua_Wood_Rimu_Trunk"
    },
    {
      "x": 1,
      "y": 14,
      "z": 1,
      "name": "Te_Whenua_Wood_Rimu_Trunk"
    },
    {
      "x": 1,
      "y": 15,
      "z": 1,
      "name": "Te_Whenua_Wood_Rimu_Trunk"
    },
    {
      "x": 1,
      "y": 16,
      "z": 1,
      "name": "Te_Whenua_Wood_Rimu_Trunk"
    },
    {
      "x": 1,
      "y": 17,
      "z": 1,
      "name": "Te_Whenua_Wood_Rimu_Trunk"
    },
    {
      "x": 1,
      "y": 18,
      "z": 1,
      "name": "Te_Whenua_Wood_Rimu_Trunk"
    },
    {
      "x": 1,
      "y": 19,
      "z": 1,
      "name": "Te_Whenua_Wood_Rimu_Trunk"
    },
    {
      "x": 1,
      "y": 20,
      "z": 1,
      "name": "Te_Whenua_Wood_Rimu_Trunk"
    },
    {
      "x": 1,
      "y": 21,
      "z": 1,
      "name": "Te_Whenua_Wood_Rimu_Trunk"
    },
    {
      "x": 1,
      "y": 22,
      "z": 1,
      "name": "Te_Whenua_Wood_Rimu_Trunk"
    },
    {
      "x": 1,
      "y": 23,
      "z": 1,
      "name": "Te_Whenua_Wood_Rimu_Trunk"
    },
    {
      "x": 1,
      "y": 24,
      "z": 1,
      "name": "Te_Whenua_Wood_Rimu_Trunk"
    },
    {
      "x": 1,
      "y": 25,
      "z": 1,
      "name": "Te_Whenua_Wood_Rimu_Trunk"
    },
    {
      "x": 1,
      "y": 26,
      "z": 1,
      "name": "Te_Whenua_Wood_Rimu_Trunk"
    },
    {
      "x": 1,
      "y": 27,
      "z": 1,
      "name": "Te_Whenua_Wood_Rimu_Trunk"
    },
    {
      "x": 1,
      "y": 28,
      "z": 1,
      "name": "Te_Whenua_Wood_Rimu_Trunk"
    },
    {
      "x": 1,
      "y": 29,
      "z": 1,
      "name": "Te_Whenua_Wood_Rimu_Trunk"
    },
    {
      "x": 1,
      "y": 30,
      "z": 1,
      "name": "Te_Whenua_Wood_Rimu_Trunk_Full"
    },
    {
      "x": 1,
      "y": 31,
      "z": 1,
      "name": "Te_Whenua_Plant_Rimu_Leaves"
    },
    {
      "x": 1,
      "y": 32,
      "z": 1,
      "name": "Te_Whenua_Plant_Rimu_Leaves"
    },
    {
      "x": 1,
      "y": 33,
      "z": 1,
      "name": "Te_Whenua_Plant_Rimu_Leaves"
    },
    {
      "x": 1,
      "y": 0,
      "z": 2,
      "name": "Te_Whenua_Wood_Rimu_Trunk"
    },
    {
      "x": 1,
      "y": 1,
      "z": 2,
      "name": "Te_Whenua_Wood_Rimu_Trunk"
    },
    {
      "x": 1,
      "y": 2,
      "z": 2,
      "name": "Te_Whenua_Wood_Rimu_Trunk"
    },
    {
      "x": 1,
      "y": 3,
      "z": 2,
      "name": "Te_Whenua_Wood_Rimu_Trunk"
    },
    {
      "x": 1,
      "y": 4,
      "z": 2,
      "name": "Te_Whenua_Wood_Rimu_Trunk"
    },
    {
      "x": 1,
      "y": 5,
      "z": 2,
      "name": "Te_Whenua_Wood_Rimu_Trunk"
    },
    {
      "x": 1,
      "y": 6,
      "z": 2,
      "name": "Te_Whenua_Wood_Rimu_Trunk"
    },
    {
      "x": 1,
      "y": 7,
      "z": 2,
      "name": "Te_Whenua_Wood_Rimu_Trunk"
    },
    {
      "x": 1,
      "y": 8,
      "z": 2,
      "name": "Te_Whenua_Wood_Rimu_Trunk"
    },
    {
      "x": 1,
      "y": 9,
      "z": 2,
      "name": "Te_Whenua_Wood_Rimu_Trunk"
    },
    {
      "x": 1,
      "y": 10,
      "z": 2,
      "name": "Te_Whenua_Wood_Rimu_Trunk"
    },
    {
      "x": 1,
      "y": 11,
      "z": 2,
      "name": "Te_Whenua_Wood_Rimu_Trunk"
    },
    {
      "x": 1,
      "y": 12,
      "z": 2,
      "name": "Te_Whenua_Wood_Rimu_Trunk"
    },
    {
      "x": 1,
      "y": 13,
      "z": 2,
      "name": "Te_Whenua_Wood_Rimu_Trunk"
    },
    {
      "x": 1,
      "y": 14,
      "z": 2,
      "name": "Te_Whenua_Wood_Rimu_Trunk"
    },
    {
      "x": 1,
      "y": 15,
      "z": 2,
      "name": "Te_Whenua_Wood_Rimu_Trunk"
    },
    {
      "x": 1,
      "y": 16,
      "z": 2,
      "name": "Te_Whenua_Wood_Rimu_Trunk"
    },
    {
      "x": 1,
      "y": 17,
      "z": 2,
      "name": "Te_Whenua_Wood_Rimu_Trunk"
    },
    {
      "x": 1,
      "y": 18,
      "z": 2,
      "name": "Te_Whenua_Wood_Rimu_Trunk"
    },
    {
      "x": 1,
      "y": 19,
      "z": 2,
      "name": "Te_Whenua_Wood_Rimu_Trunk"
    },
    {
      "x": 1,
      "y": 20,
      "z": 2,
      "name": "Te_Whenua_Wood_Rimu_Trunk"
    },
    {
      "x": 1,
      "y": 21,
      "z": 2,
      "name": "Te_Whenua_Wood_Rimu_Trunk"
    },
    {
      "x": 1,
      "y": 22,
      "z": 2,
      "name": "Te_Whenua_Wood_Rimu_Trunk"
    },
    {
      "x": 1,
      "y": 23,
      "z": 2,
      "name": "Te_Whenua_Wood_Rimu_Trunk"
    },
    {
      "x": 1,
      "y": 24,
      "z": 2,
      "name": "Te_Whenua_Wood_Rimu_Trunk"
    },
    {
      "x": 1,
      "y": 25,
      "z": 2,
      "name": "Te_Whenua_Wood_Rimu_Trunk"
    },
    {
      "x": 1,
      "y": 26,
      "z": 2,
      "name": "Te_Whenua_Wood_Rimu_Trunk"
    },
    {
      "x": 1,
      "y": 27,
      "z": 2,
      "name": "Te_Whenua_Wood_Rimu_Trunk"
    },
    {
      "x": 1,
      "y": 28,
      "z": 2,
      "name": "Te_Whenua_Wood_Rimu_Trunk"
    },
    {
      "x": 1,
      "y": 29,
      "z": 2,
      "name": "Te_Whenua_Wood_Rimu_Trunk"
    },
    {
      "x": 1,
      "y": 30,
      "z": 2,
      "name": "Te_Whenua_Wood_Rimu_Trunk_Full"
    },
    {
      "x": 1,
      "y": 31,
      "z": 2,
      "name": "Te_Whenua_Plant_Rimu_Leaves"
    },
    {
      "x": 1,
      "y": 32,
      "z": 2,
      "name": "Te_Whenua_Plant_Rimu_Leaves"
    },
    {
      "x": 1,
      "y": 0,
      "z": 3,
      "name": "Te_Whenua_Wood_Rimu_Trunk"
    },
    {
      "x": 1,
      "y": 1,
      "z": 3,
      "name": "Te_Whenua_Wood_Rimu_Trunk"
    },
    {
      "x": 1,
      "y": 2,
      "z": 3,
      "name": "Te_Whenua_Wood_Rimu_Trunk_Full"
    },
    {
      "x": 1,
      "y": 15,
      "z": 3,
      "name": "Te_Whenua_Plant_Rimu_Leaves"
    },
    {
      "x": 1,
      "y": 16,
      "z": 3,
      "name": "Te_Whenua_Plant_Rimu_Leaves"
    },
    {
      "x": 1,
      "y": 17,
      "z": 3,
      "name": "Te_Whenua_Plant_Rimu_Leaves"
    },
    {
      "x": 1,
      "y": 18,
      "z": 3,
      "name": "Te_Whenua_Plant_Rimu_Leaves"
    },
    {
      "x": 1,
      "y": 19,
      "z": 3,
      "name": "Te_Whenua_Wood_Rimu_Branch_Long",
      "rotation": 4
    },
    {
      "x": 1,
      "y": 20,
      "z": 3,
      "name": "Te_Whenua_Plant_Rimu_Leaves"
    },
    {
      "x": 1,
      "y": 21,
      "z": 3,
      "name": "Te_Whenua_Plant_Rimu_Leaves"
    },
    {
      "x": 1,
      "y": 24,
      "z": 3,
      "name": "Te_Whenua_Plant_Rimu_Leaves"
    },
    {
      "x": 1,
      "y": 25,
      "z": 3,
      "name": "Te_Whenua_Plant_Rimu_Leaves"
    },
    {
      "x": 1,
      "y": 26,
      "z": 3,
      "name": "Te_Whenua_Plant_Rimu_Leaves"
    },
    {
      "x": 1,
      "y": 27,
      "z": 3,
      "name": "Te_Whenua_Plant_Rimu_Leaves"
    },
    {
      "x": 1,
      "y": 28,
      "z": 3,
      "name": "Te_Whenua_Plant_Rimu_Leaves"
    },
    {
      "x": 1,
      "y": 29,
      "z": 3,
      "name": "Te_Whenua_Plant_Rimu_Leaves"
    },
    {
      "x": 1,
      "y": 30,
      "z": 3,
      "name": "Te_Whenua_Plant_Rimu_Leaves"
    },
    {
      "x": 1,
      "y": 31,
      "z": 3,
      "name": "Te_Whenua_Plant_Rimu_Leaves"
    },
    {
      "x": 1,
      "y": 16,
      "z": 4,
      "name": "Te_Whenua_Plant_Rimu_Leaves"
    },
    {
      "x": 1,
      "y": 17,
      "z": 4,
      "name": "Te_Whenua_Plant_Rimu_Leaves"
    },
    {
      "x": 1,
      "y": 18,
      "z": 4,
      "name": "Te_Whenua_Plant_Rimu_Leaves"
    },
    {
      "x": 1,
      "y": 19,
      "z": 4,
      "name": "Te_Whenua_Plant_Rimu_Leaves"
    },
    {
      "x": 1,
      "y": 20,
      "z": 4,
      "name": "Te_Whenua_Plant_Rimu_Leaves"
    },
    {
      "x": 1,
      "y": 21,
      "z": 4,
      "name": "Te_Whenua_Plant_Rimu_Leaves"
    },
    {
      "x": 1,
      "y": 18,
      "z": 5,
      "name": "Te_Whenua_Plant_Rimu_Leaves"
    },
    {
      "x": 1,
      "y": 19,
      "z": 5,
      "name": "Te_Whenua_Plant_Rimu_Leaves"
    },
    {
      "x": 1,
      "y": 20,
      "z": 5,
      "name": "Te_Whenua_Plant_Rimu_Leaves"
    },
    {
      "x": 2,
      "y": 20,
      "z": -4,
      "name": "Te_Whenua_Plant_Rimu_Leaves"
    },
    {
      "x": 2,
      "y": 21,
      "z": -4,
      "name": "Te_Whenua_Plant_Rimu_Leaves"
    },
    {
      "x": 2,
      "y": 22,
      "z": -4,
      "name": "Te_Whenua_Plant_Rimu_Leaves"
    },
    {
      "x": 2,
      "y": 20,
      "z": -3,
      "name": "Te_Whenua_Plant_Rimu_Leaves"
    },
    {
      "x": 2,
      "y": 21,
      "z": -3,
      "name": "Te_Whenua_Plant_Rimu_Leaves"
    },
    {
      "x": 2,
      "y": 22,
      "z": -3,
      "name": "Te_Whenua_Plant_Rimu_Leaves"
    },
    {
      "x": 2,
      "y": 19,
      "z": -2,
      "name": "Te_Whenua_Plant_Rimu_Leaves"
    },
    {
      "x": 2,
      "y": 20,
      "z": -2,
      "name": "Te_Whenua_Plant_Rimu_Leaves"
    },
    {
      "x": 2,
      "y": 21,
      "z": -2,
      "name": "Te_Whenua_Plant_Rimu_Leaves"
    },
    {
      "x": 2,
      "y": 22,
      "z": -2,
      "name": "Te_Whenua_Plant_Rimu_Leaves"
    },
    {
      "x": 2,
      "y": 23,
      "z": -2,
      "name": "Te_Whenua_Plant_Rimu_Leaves"
    },
    {
      "x": 2,
      "y": 16,
      "z": -1,
      "name": "Te_Whenua_Plant_Rimu_Leaves"
    },
    {
      "x": 2,
      "y": 17,
      "z": -1,
      "name": "Te_Whenua_Plant_Rimu_Leaves"
    },
    {
      "x": 2,
      "y": 18,
      "z": -1,
      "name": "Te_Whenua_Plant_Rimu_Leaves"
    },
    {
      "x": 2,
      "y": 19,
      "z": -1,
      "name": "Te_Whenua_Plant_Rimu_Leaves"
    },
    {
      "x": 2,
      "y": 20,
      "z": -1,
      "name": "Te_Whenua_Plant_Rimu_Leaves"
    },
    {
      "x": 2,
      "y": 21,
      "z": -1,
      "name": "Te_Whenua_Plant_Rimu_Leaves"
    },
    {
      "x": 2,
      "y": 22,
      "z": -1,
      "name": "Te_Whenua_Plant_Rimu_Leaves"
    },
    {
      "x": 2,
      "y": 23,
      "z": -1,
      "name": "Te_Whenua_Plant_Rimu_Leaves"
    },
    {
      "x": 2,
      "y": 15,
      "z": 0,
      "name": "Te_Whenua_Plant_Rimu_Leaves"
    },
    {
      "x": 2,
      "y": 16,
      "z": 0,
      "name": "Te_Whenua_Plant_Rimu_Leaves"
    },
    {
      "x": 2,
      "y": 17,
      "z": 0,
      "name": "Te_Whenua_Plant_Rimu_Leaves"
    },
    {
      "x": 2,
      "y": 18,
      "z": 0,
      "name": "Te_Whenua_Plant_Rimu_Leaves"
    },
    {
      "x": 2,
      "y": 19,
      "z": 0,
      "name": "Te_Whenua_Plant_Rimu_Leaves"
    },
    {
      "x": 2,
      "y": 20,
      "z": 0,
      "name": "Te_Whenua_Plant_Rimu_Leaves"
    },
    {
      "x": 2,
      "y": 21,
      "z": 0,
      "name": "Te_Whenua_Plant_Rimu_Leaves"
    },
    {
      "x": 2,
      "y": 22,
      "z": 0,
      "name": "Te_Whenua_Plant_Rimu_Leaves"
    },
    {
      "x": 2,
      "y": 23,
      "z": 0,
      "name": "Te_Whenua_Plant_Rimu_Leaves"
    },
    {
      "x": 2,
      "y": 24,
      "z": 0,
      "name": "Te_Whenua_Plant_Rimu_Leaves"
    },
    {
      "x": 2,
      "y": 25,
      "z": 0,
      "name": "Te_Whenua_Plant_Rimu_Leaves"
    },
    {
      "x": 2,
      "y": 26,
      "z": 0,
      "name": "Te_Whenua_Plant_Rimu_Leaves"
    },
    {
      "x": 2,
      "y": 27,
      "z": 0,
      "name": "Te_Whenua_Plant_Rimu_Leaves"
    },
    {
      "x": 2,
      "y": 29,
      "z": 0,
      "name": "Te_Whenua_Plant_Rimu_Leaves"
    },
    {
      "x": 2,
      "y": 30,
      "z": 0,
      "name": "Te_Whenua_Plant_Rimu_Leaves"
    },
    {
      "x": 2,
      "y": 31,
      "z": 0,
      "name": "Te_Whenua_Plant_Rimu_Leaves"
    },
    {
      "x": 2,
      "y": 0,
      "z": 1,
      "name": "Te_Whenua_Wood_Rimu_Trunk"
    },
    {
      "x": 2,
      "y": 1,
      "z": 1,
      "name": "Te_Whenua_Wood_Rimu_Trunk"
    },
    {
      "x": 2,
      "y": 2,
      "z": 1,
      "name": "Te_Whenua_Wood_Rimu_Trunk_Full"
    },
    {
      "x": 2,
      "y": 12,
      "z": 1,
      "name": "Te_Whenua_Wood_Rimu_Branch_Short",
      "rotation": 1
    },
    {
      "x": 2,
      "y": 14,
      "z": 1,
      "name": "Te_Whenua_Plant_Rimu_Leaves"
    },
    {
      "x": 2,
      "y": 15,
      "z": 1,
      "name": "Te_Whenua_Plant_Rimu_Leaves"
    },
    {
      "x": 2,
      "y": 16,
      "z": 1,
      "name": "Te_Whenua_Wood_Rimu_Branch_Long",
      "rotation": 5
    },
    {
      "x": 2,
      "y": 17,
      "z": 1,
      "name": "Te_Whenua_Plant_Rimu_Leaves"
    },
    {
      "x": 2,
      "y": 18,
      "z": 1,
      "name": "Te_Whenua_Plant_Rimu_Leaves"
    },
    {
      "x": 2,
      "y": 19,
      "z": 1,
      "name": "Te_Whenua_Wood_Rimu_Branch_Long",
      "rotation": 5
    },
    {
      "x": 2,
      "y": 20,
      "z": 1,
      "name": "Te_Whenua_Plant_Rimu_Leaves"
    },
    {
      "x": 2,
      "y": 21,
      "z": 1,
      "name": "Te_Whenua_Plant_Rimu_Leaves"
    },
    {
      "x": 2,
      "y": 22,
      "z": 1,
      "name": "Te_Whenua_Plant_Rimu_Leaves"
    },
    {
      "x": 2,
      "y": 23,
      "z": 1,
      "name": "Te_Whenua_Plant_Rimu_Leaves"
    },
    {
      "x": 2,
      "y": 24,
      "z": 1,
      "name": "Te_Whenua_Plant_Rimu_Leaves"
    },
    {
      "x": 2,
      "y": 25,
      "z": 1,
      "name": "Te_Whenua_Plant_Rimu_Leaves"
    },
    {
      "x": 2,
      "y": 26,
      "z": 1,
      "name": "Te_Whenua_Wood_Rimu_Branch_Long",
      "rotation": 5
    },
    {
      "x": 2,
      "y": 27,
      "z": 1,
      "name": "Te_Whenua_Plant_Rimu_Leaves"
    },
    {
      "x": 2,
      "y": 28,
      "z": 1,
      "name": "Te_Whenua_Plant_Rimu_Leaves"
    },
    {
      "x": 2,
      "y": 29,
      "z": 1,
      "name": "Te_Whenua_Plant_Rimu_Leaves"
    },
    {
      "x": 2,
      "y": 30,
      "z": 1,
      "name": "Te_Whenua_Wood_Rimu_Branch_Long",
      "rotation": 5
    },
    {
      "x": 2,
      "y": 31,
      "z": 1,
      "name": "Te_Whenua_Plant_Rimu_Leaves"
    },
    {
      "x": 2,
      "y": 32,
      "z": 1,
      "name": "Te_Whenua_Plant_Rimu_Leaves"
    },
    {
      "x": 2,
      "y": 0,
      "z": 2,
      "name": "Te_Whenua_Wood_Rimu_Trunk"
    },
    {
      "x": 2,
      "y": 1,
      "z": 2,
      "name": "Te_Whenua_Wood_Rimu_Trunk_Full"
    },
    {
      "x": 2,
      "y": 15,
      "z": 2,
      "name": "Te_Whenua_Plant_Rimu_Leaves"
    },
    {
      "x": 2,
      "y": 16,
      "z": 2,
      "name": "Te_Whenua_Plant_Rimu_Leaves"
    },
    {
      "x": 2,
      "y": 17,
      "z": 2,
      "name": "Te_Whenua_Plant_Rimu_Leaves"
    },
    {
      "x": 2,
      "y": 18,
      "z": 2,
      "name": "Te_Whenua_Plant_Rimu_Leaves"
    },
    {
      "x": 2,
      "y": 19,
      "z": 2,
      "name": "Te_Whenua_Plant_Rimu_Leaves"
    },
    {
      "x": 2,
      "y": 20,
      "z": 2,
      "name": "Te_Whenua_Plant_Rimu_Leaves"
    },
    {
      "x": 2,
      "y": 21,
      "z": 2,
      "name": "Te_Whenua_Wood_Rimu_Branch_Long",
      "rotation": 5
    },
    {
      "x": 2,
      "y": 22,
      "z": 2,
      "name": "Te_Whenua_Plant_Rimu_Leaves"
    },
    {
      "x": 2,
      "y": 23,
      "z": 2,
      "name": "Te_Whenua_Plant_Rimu_Leaves"
    },
    {
      "x": 2,
      "y": 24,
      "z": 2,
      "name": "Te_Whenua_Plant_Rimu_Leaves"
    },
    {
      "x": 2,
      "y": 25,
      "z": 2,
      "name": "Te_Whenua_Plant_Rimu_Leaves"
    },
    {
      "x": 2,
      "y": 26,
      "z": 2,
      "name": "Te_Whenua_Plant_Rimu_Leaves"
    },
    {
      "x": 2,
      "y": 27,
      "z": 2,
      "name": "Te_Whenua_Plant_Rimu_Leaves"
    },
    {
      "x": 2,
      "y": 28,
      "z": 2,
      "name": "Te_Whenua_Plant_Rimu_Leaves"
    },
    {
      "x": 2,
      "y": 29,
      "z": 2,
      "name": "Te_Whenua_Plant_Rimu_Leaves"
    },
    {
      "x": 2,
      "y": 30,
      "z": 2,
      "name": "Te_Whenua_Plant_Rimu_Leaves"
    },
    {
      "x": 2,
      "y": 31,
      "z": 2,
      "name": "Te_Whenua_Plant_Rimu_Leaves"
    },
    {
      "x": 2,
      "y": 15,
      "z": 3,
      "name": "Te_Whenua_Plant_Rimu_Leaves"
    },
    {
      "x": 2,
      "y": 16,
      "z": 3,
      "name": "Te_Whenua_Plant_Rimu_Leaves"
    },
    {
      "x": 2,
      "y": 17,
      "z": 3,
      "name": "Te_Whenua_Plant_Rimu_Leaves"
    },
    {
      "x": 2,
      "y": 18,
      "z": 3,
      "name": "Te_Whenua_Plant_Rimu_Leaves"
    },
    {
      "x": 2,
      "y": 19,
      "z": 3,
      "name": "Te_Whenua_Plant_Rimu_Leaves"
    },
    {
      "x": 2,
      "y": 20,
      "z": 3,
      "name": "Te_Whenua_Plant_Rimu_Leaves"
    },
    {
      "x": 2,
      "y": 21,
      "z": 3,
      "name": "Te_Whenua_Plant_Rimu_Leaves"
    },
    {
      "x": 2,
      "y": 22,
      "z": 3,
      "name": "Te_Whenua_Plant_Rimu_Leaves"
    },
    {
      "x": 2,
      "y": 24,
      "z": 3,
      "name": "Te_Whenua_Plant_Rimu_Leaves"
    },
    {
      "x": 2,
      "y": 25,
      "z": 3,
      "name": "Te_Whenua_Plant_Rimu_Leaves"
    },
    {
      "x": 2,
      "y": 26,
      "z": 3,
      "name": "Te_Whenua_Plant_Rimu_Leaves"
    },
    {
      "x": 2,
      "y": 27,
      "z": 3,
      "name": "Te_Whenua_Plant_Rimu_Leaves"
    },
    {
      "x": 2,
      "y": 28,
      "z": 3,
      "name": "Te_Whenua_Plant_Rimu_Leaves"
    },
    {
      "x": 2,
      "y": 29,
      "z": 3,
      "name": "Te_Whenua_Plant_Rimu_Leaves"
    },
    {
      "x": 2,
      "y": 16,
      "z": 4,
      "name": "Te_Whenua_Plant_Rimu_Leaves"
    },
    {
      "x": 2,
      "y": 17,
      "z": 4,
      "name": "Te_Whenua_Plant_Rimu_Leaves"
    },
    {
      "x": 2,
      "y": 18,
      "z": 4,
      "name": "Te_Whenua_Plant_Rimu_Leaves"
    },
    {
      "x": 2,
      "y": 19,
      "z": 4,
      "name": "Te_Whenua_Plant_Rimu_Leaves"
    },
    {
      "x": 2,
      "y": 20,
      "z": 4,
      "name": "Te_Whenua_Plant_Rimu_Leaves"
    },
    {
      "x": 2,
      "y": 26,
      "z": 4,
      "name": "Te_Whenua_Plant_Rimu_Leaves"
    },
    {
      "x": 2,
      "y": 27,
      "z": 4,
      "name": "Te_Whenua_Plant_Rimu_Leaves"
    },
    {
      "x": 2,
      "y": 28,
      "z": 4,
      "name": "Te_Whenua_Plant_Rimu_Leaves"
    },
    {
      "x": 3,
      "y": 20,
      "z": -2,
      "name": "Te_Whenua_Plant_Rimu_Leaves"
    },
    {
      "x": 3,
      "y": 21,
      "z": -2,
      "name": "Te_Whenua_Plant_Rimu_Leaves"
    },
    {
      "x": 3,
      "y": 22,
      "z": -2,
      "name": "Te_Whenua_Plant_Rimu_Leaves"
    },
    {
      "x": 3,
      "y": 16,
      "z": -1,
      "name": "Te_Whenua_Plant_Rimu_Leaves"
    },
    {
      "x": 3,
      "y": 17,
      "z": -1,
      "name": "Te_Whenua_Plant_Rimu_Leaves"
    },
    {
      "x": 3,
      "y": 18,
      "z": -1,
      "name": "Te_Whenua_Plant_Rimu_Leaves"
    },
    {
      "x": 3,
      "y": 19,
      "z": -1,
      "name": "Te_Whenua_Plant_Rimu_Leaves"
    },
    {
      "x": 3,
      "y": 20,
      "z": -1,
      "name": "Te_Whenua_Plant_Rimu_Leaves"
    },
    {
      "x": 3,
      "y": 25,
      "z": -1,
      "name": "Te_Whenua_Plant_Rimu_Leaves"
    },
    {
      "x": 3,
      "y": 26,
      "z": -1,
      "name": "Te_Whenua_Plant_Rimu_Leaves"
    },
    {
      "x": 3,
      "y": 27,
      "z": -1,
      "name": "Te_Whenua_Plant_Rimu_Leaves"
    },
    {
      "x": 3,
      "y": 15,
      "z": 0,
      "name": "Te_Whenua_Plant_Rimu_Leaves"
    },
    {
      "x": 3,
      "y": 16,
      "z": 0,
      "name": "Te_Whenua_Plant_Rimu_Leaves"
    },
    {
      "x": 3,
      "y": 17,
      "z": 0,
      "name": "Te_Whenua_Plant_Rimu_Leaves"
    },
    {
      "x": 3,
      "y": 18,
      "z": 0,
      "name": "Te_Whenua_Plant_Rimu_Leaves"
    },
    {
      "x": 3,
      "y": 19,
      "z": 0,
      "name": "Te_Whenua_Plant_Rimu_Leaves"
    },
    {
      "x": 3,
      "y": 20,
      "z": 0,
      "name": "Te_Whenua_Plant_Rimu_Leaves"
    },
    {
      "x": 3,
      "y": 21,
      "z": 0,
      "name": "Te_Whenua_Plant_Rimu_Leaves"
    },
    {
      "x": 3,
      "y": 22,
      "z": 0,
      "name": "Te_Whenua_Plant_Rimu_Leaves"
    },
    {
      "x": 3,
      "y": 23,
      "z": 0,
      "name": "Te_Whenua_Plant_Rimu_Leaves"
    },
    {
      "x": 3,
      "y": 24,
      "z": 0,
      "name": "Te_Whenua_Plant_Rimu_Leaves"
    },
    {
      "x": 3,
      "y": 25,
      "z": 0,
      "name": "Te_Whenua_Plant_Rimu_Leaves"
    },
    {
      "x": 3,
      "y": 26,
      "z": 0,
      "name": "Te_Whenua_Plant_Rimu_Leaves"
    },
    {
      "x": 3,
      "y": 27,
      "z": 0,
      "name": "Te_Whenua_Plant_Rimu_Leaves"
    },
    {
      "x": 3,
      "y": 28,
      "z": 0,
      "name": "Te_Whenua_Plant_Rimu_Leaves"
    },
    {
      "x": 3,
      "y": 29,
      "z": 0,
      "name": "Te_Whenua_Plant_Rimu_Leaves"
    },
    {
      "x": 3,
      "y": 30,
      "z": 0,
      "name": "Te_Whenua_Plant_Rimu_Leaves"
    },
    {
      "x": 3,
      "y": 31,
      "z": 0,
      "name": "Te_Whenua_Plant_Rimu_Leaves"
    },
    {
      "x": 3,
      "y": 32,
      "z": 0,
      "name": "Te_Whenua_Plant_Rimu_Leaves"
    },
    {
      "x": 3,
      "y": 15,
      "z": 1,
      "name": "Te_Whenua_Plant_Rimu_Leaves"
    },
    {
      "x": 3,
      "y": 16,
      "z": 1,
      "name": "Te_Whenua_Plant_Rimu_Leaves"
    },
    {
      "x": 3,
      "y": 17,
      "z": 1,
      "name": "Te_Whenua_Plant_Rimu_Leaves"
    },
    {
      "x": 3,
      "y": 18,
      "z": 1,
      "name": "Te_Whenua_Plant_Rimu_Leaves"
    },
    {
      "x": 3,
      "y": 19,
      "z": 1,
      "name": "Te_Whenua_Wood_Rimu_Branch_Long",
      "rotation": 5
    },
    {
      "x": 3,
      "y": 20,
      "z": 1,
      "name": "Te_Whenua_Plant_Rimu_Leaves"
    },
    {
      "x": 3,
      "y": 21,
      "z": 1,
      "name": "Te_Whenua_Plant_Rimu_Leaves"
    },
    {
      "x": 3,
      "y": 22,
      "z": 1,
      "name": "Te_Whenua_Plant_Rimu_Leaves"
    },
    {
      "x": 3,
      "y": 23,
      "z": 1,
      "name": "Te_Whenua_Plant_Rimu_Leaves"
    },
    {
      "x": 3,
      "y": 24,
      "z": 1,
      "name": "Te_Whenua_Plant_Rimu_Leaves"
    },
    {
      "x": 3,
      "y": 25,
      "z": 1,
      "name": "Te_Whenua_Plant_Rimu_Leaves"
    },
    {
      "x": 3,
      "y": 26,
      "z": 1,
      "name": "Te_Whenua_Wood_Rimu_Branch_Long",
      "rotation": 5
    },
    {
      "x": 3,
      "y": 27,
      "z": 1,
      "name": "Te_Whenua_Plant_Rimu_Leaves"
    },
    {
      "x": 3,
      "y": 28,
      "z": 1,
      "name": "Te_Whenua_Plant_Rimu_Leaves"
    },
    {
      "x": 3,
      "y": 29,
      "z": 1,
      "name": "Te_Whenua_Plant_Rimu_Leaves"
    },
    {
      "x": 3,
      "y": 30,
      "z": 1,
      "name": "Te_Whenua_Plant_Rimu_Leaves"
    },
    {
      "x": 3,
      "y": 31,
      "z": 1,
      "name": "Te_Whenua_Plant_Rimu_Leaves"
    },
    {
      "x": 3,
      "y": 32,
      "z": 1,
      "name": "Te_Whenua_Plant_Rimu_Leaves"
    },
    {
      "x": 3,
      "y": 33,
      "z": 1,
      "name": "Te_Whenua_Plant_Rimu_Leaves"
    },
    {
      "x": 3,
      "y": 17,
      "z": 2,
      "name": "Te_Whenua_Plant_Rimu_Leaves"
    },
    {
      "x": 3,
      "y": 18,
      "z": 2,
      "name": "Te_Whenua_Plant_Rimu_Leaves"
    },
    {
      "x": 3,
      "y": 19,
      "z": 2,
      "name": "Te_Whenua_Plant_Rimu_Leaves"
    },
    {
      "x": 3,
      "y": 20,
      "z": 2,
      "name": "Te_Whenua_Plant_Rimu_Leaves"
    },
    {
      "x": 3,
      "y": 21,
      "z": 2,
      "name": "Te_Whenua_Plant_Rimu_Leaves"
    },
    {
      "x": 3,
      "y": 22,
      "z": 2,
      "name": "Te_Whenua_Plant_Rimu_Leaves"
    },
    {
      "x": 3,
      "y": 23,
      "z": 2,
      "name": "Te_Whenua_Plant_Rimu_Leaves"
    },
    {
      "x": 3,
      "y": 24,
      "z": 2,
      "name": "Te_Whenua_Plant_Rimu_Leaves"
    },
    {
      "x": 3,
      "y": 25,
      "z": 2,
      "name": "Te_Whenua_Plant_Rimu_Leaves"
    },
    {
      "x": 3,
      "y": 26,
      "z": 2,
      "name": "Te_Whenua_Plant_Rimu_Leaves"
    },
    {
      "x": 3,
      "y": 27,
      "z": 2,
      "name": "Te_Whenua_Plant_Rimu_Leaves"
    },
    {
      "x": 3,
      "y": 28,
      "z": 2,
      "name": "Te_Whenua_Plant_Rimu_Leaves"
    },
    {
      "x": 3,
      "y": 29,
      "z": 2,
      "name": "Te_Whenua_Plant_Rimu_Leaves"
    },
    {
      "x": 3,
      "y": 30,
      "z": 2,
      "name": "Te_Whenua_Plant_Rimu_Leaves"
    },
    {
      "x": 3,
      "y": 31,
      "z": 2,
      "name": "Te_Whenua_Plant_Rimu_Leaves"
    },
    {
      "x": 3,
      "y": 32,
      "z": 2,
      "name": "Te_Whenua_Plant_Rimu_Leaves"
    },
    {
      "x": 3,
      "y": 16,
      "z": 3,
      "name": "Te_Whenua_Plant_Rimu_Leaves"
    },
    {
      "x": 3,
      "y": 17,
      "z": 3,
      "name": "Te_Whenua_Plant_Rimu_Leaves"
    },
    {
      "x": 3,
      "y": 18,
      "z": 3,
      "name": "Te_Whenua_Plant_Rimu_Leaves"
    },
    {
      "x": 3,
      "y": 21,
      "z": 3,
      "name": "Te_Whenua_Plant_Rimu_Leaves"
    },
    {
      "x": 3,
      "y": 22,
      "z": 3,
      "name": "Te_Whenua_Plant_Rimu_Leaves"
    },
    {
      "x": 3,
      "y": 23,
      "z": 3,
      "name": "Te_Whenua_Plant_Rimu_Leaves"
    },
    {
      "x": 3,
      "y": 26,
      "z": 3,
      "name": "Te_Whenua_Plant_Rimu_Leaves"
    },
    {
      "x": 3,
      "y": 27,
      "z": 3,
      "name": "Te_Whenua_Plant_Rimu_Leaves"
    },
    {
      "x": 3,
      "y": 28,
      "z": 3,
      "name": "Te_Whenua_Plant_Rimu_Leaves"
    },
    {
      "x": 4,
      "y": 16,
      "z": 0,
      "name": "Te_Whenua_Plant_Rimu_Leaves"
    },
    {
      "x": 4,
      "y": 17,
      "z": 0,
      "name": "Te_Whenua_Plant_Rimu_Leaves"
    },
    {
      "x": 4,
      "y": 18,
      "z": 0,
      "name": "Te_Whenua_Plant_Rimu_Leaves"
    },
    {
      "x": 4,
      "y": 19,
      "z": 0,
      "name": "Te_Whenua_Plant_Rimu_Leaves"
    },
    {
      "x": 4,
      "y": 20,
      "z": 0,
      "name": "Te_Whenua_Plant_Rimu_Leaves"
    },
    {
      "x": 4,
      "y": 25,
      "z": 0,
      "name": "Te_Whenua_Plant_Rimu_Leaves"
    },
    {
      "x": 4,
      "y": 26,
      "z": 0,
      "name": "Te_Whenua_Plant_Rimu_Leaves"
    },
    {
      "x": 4,
      "y": 27,
      "z": 0,
      "name": "Te_Whenua_Plant_Rimu_Leaves"
    },
    {
      "x": 4,
      "y": 17,
      "z": 1,
      "name": "Te_Whenua_Plant_Rimu_Leaves"
    },
    {
      "x": 4,
      "y": 18,
      "z": 1,
      "name": "Te_Whenua_Plant_Rimu_Leaves"
    },
    {
      "x": 4,
      "y": 19,
      "z": 1,
      "name": "Te_Whenua_Plant_Rimu_Leaves"
    },
    {
      "x": 4,
      "y": 20,
      "z": 1,
      "name": "Te_Whenua_Plant_Rimu_Leaves"
    },
    {
      "x": 4,
      "y": 21,
      "z": 1,
      "name": "Te_Whenua_Plant_Rimu_Leaves"
    },
    {
      "x": 4,
      "y": 25,
      "z": 1,
      "name": "Te_Whenua_Plant_Rimu_Leaves"
    },
    {
      "x": 4,
      "y": 26,
      "z": 1,
      "name": "Te_Whenua_Plant_Rimu_Leaves"
    },
    {
      "x": 4,
      "y": 27,
      "z": 1,
      "name": "Te_Whenua_Plant_Rimu_Leaves"
    },
    {
      "x": 4,
      "y": 28,
      "z": 1,
      "name": "Te_Whenua_Plant_Rimu_Leaves"
    },
    {
      "x": 4,
      "y": 29,
      "z": 1,
      "name": "Te_Whenua_Plant_Rimu_Leaves"
    },
    {
      "x": 4,
      "y": 30,
      "z": 1,
      "name": "Te_Whenua_Plant_Rimu_Leaves"
    },
    {
      "x": 4,
      "y": 31,
      "z": 1,
      "name": "Te_Whenua_Plant_Rimu_Leaves"
    },
    {
      "x": 4,
      "y": 32,
      "z": 1,
      "name": "Te_Whenua_Plant_Rimu_Leaves"
    },
    {
      "x": 4,
      "y": 18,
      "z": 2,
      "name": "Te_Whenua_Plant_Rimu_Leaves"
    },
    {
      "x": 4,
      "y": 19,
      "z": 2,
      "name": "Te_Whenua_Plant_Rimu_Leaves"
    },
    {
      "x": 4,
      "y": 20,
      "z": 2,
      "name": "Te_Whenua_Plant_Rimu_Leaves"
    },
    {
      "x": 4,
      "y": 21,
      "z": 2,
      "name": "Te_Whenua_Plant_Rimu_Leaves"
    },
    {
      "x": 4,
      "y": 22,
      "z": 2,
      "name": "Te_Whenua_Plant_Rimu_Leaves"
    },
    {
      "x": 4,
      "y": 23,
      "z": 2,
      "name": "Te_Whenua_Plant_Rimu_Leaves"
    },
    {
      "x": 5,
      "y": 18,
      "z": 1,
      "name": "Te_Whenua_Plant_Rimu_Leaves"
    },
    {
      "x": 5,
      "y": 19,
      "z": 1,
      "name": "Te_Whenua_Plant_Rimu_Leaves"
    },
    {
      "x": 5,
      "y": 20,
      "z": 1,
      "name": "Te_Whenua_Plant_Rimu_Leaves"
    }
  ]
}