{
  "version": 8,
  "blockIdVersion": 11,
  "anchorX": -1,
  "anchorY": 1,
  "anchorZ": 0,
  "blocks": [
    {
      "x": -3,
      "y": 10,
      "z": -1,
      "name": "Te_Whenua_Plant_Rimu_Leaves",
      "support": 15
    },
    {
      "x": -3,
      "y": 9,
      "z": 0,
      "name": "Te_Whenua_Plant_Rimu_Leaves",
      "support": 15
    },
    {
      "x": -3,
      "y": 10,
      "z": 0,
      "name": "Te_Whenua_Plant_Rimu_Leaves",
      "support": 15
    },
    {
      "x": -3,
      "y": 15,
      "z": 0,
      "name": "Te_Whenua_Plant_Rimu_Leaves",
      "support": 15
    },
    {
      "x": -3,
      "y": 16,
      "z": 0,
      "name": "Te_Whenua_Plant_Rimu_Leaves",
      "support": 15
    },
    {
      "x": -3,
      "y": 9,
      "z": 1,
      "name": "Te_Whenua_Plant_Rimu_Leaves",
      "support": 15
    },
    {
      "x": -3,
      "y": 10,
      "z": 1,
      "name": "Te_Whenua_Plant_Rimu_Leaves",
      "support": 15
    },
    {
      "x": -3,
      "y": 11,
      "z": 1,
      "name": "Te_Whenua_Plant_Rimu_Leaves",
      "support": 15
    },
    {
      "x": -2,
      "y": 9,
      "z": -2,
      "name": "Te_Whenua_Plant_Rimu_Leaves",
      "support": 15
    },
    {
      "x": -2,
      "y": 10,
      "z": -2,
      "name": "Te_Whenua_Plant_Rimu_Leaves",
      "support": 15
    },
    {
      "x": -2,
      "y": 11,
      "z": -2,
      "name": "Te_Whenua_Plant_Rimu_Leaves",
      "support": 15
    },
    {
      "x": -2,
      "y": 0,
      "z": -1,
      "name": "Te_Whenua_Wood_Rimu_Trunk",
      "support": 15
    },
    {
      "x": -2,
      "y": 1,
      "z": -1,
      "name": "Te_Whenua_Wood_Rimu_Trunk_Full",
      "support": 15
    },
    {
      "x": -2,
      "y": 9,
      "z": -1,
      "name": "Te_Whenua_Plant_Rimu_Leaves",
      "support": 15
    },
    {
      "x": -2,
      "y": 10,
      "z": -1,
      "name": "Te_Whenua_Plant_Rimu_Leaves",
      "support": 15
    },
    {
      "x": -2,
      "y": 11,
      "z": -1,
      "name": "Te_Whenua_Plant_Rimu_Leaves",
      "support": 15
    },
    {
      "x": -2,
      "y": 13,
      "z": -1,
      "name": "Te_Whenua_Plant_Rimu_Leaves",
      "support": 15
    },
    {
      "x": -2,
      "y": 8,
      "z": 0,
      "name": "Te_Whenua_Wood_Rimu_Branch_Long",
      "support": 15,
      "rotation": 5
    },
    {
      "x": -2,
      "y": 9,
      "z": 0,
      "name": "Te_Whenua_Plant_Rimu_Leaves",
      "support": 15
    },
    {
      "x": -2,
      "y": 10,
      "z": 0,
      "name": "Te_Whenua_Plant_Rimu_Leaves",
      "support": 15
    },
    {
      "x": -2,
      "y": 11,
      "z": 0,
      "name": "Te_Whenua_Plant_Rimu_Leaves",
      "support": 15
    },
    {
      "x": -2,
      "y": 12,
      "z": 0,
      "name": "Te_Whenua_Plant_Rimu_Leaves",
      "support": 15
    },
    {
      "x": -2,
      "y": 13,
      "z": 0,
      "name": "Te_Whenua_Plant_Rimu_Leaves",
      "support": 15
    },
    {
      "x": -2,
      "y": 14,
      "z": 0,
      "name": "Te_Whenua_Plant_Rimu_Leaves",
      "support": 15
    },
    {
      "x": -2,
      "y": 15,
      "z": 0,
      "name": "Te_Whenua_Plant_Rimu_Leaves",
      "support": 15
    },
    {
      "x": -2,
      "y": 16,
      "z": 0,
      "name": "Te_Whenua_Plant_Rimu_Leaves",
      "support": 15
    },
    {
      "x": -2,
      "y": 17,
      "z": 0,
      "name": "Te_Whenua_Plant_Rimu_Leaves",
      "support": 15
    },
    {
      "x": -2,
      "y": 9,
      "z": 1,
      "name": "Te_Whenua_Plant_Rimu_Leaves",
      "support": 15
    },
    {
      "x": -2,
      "y": 10,
      "z": 1,
      "name": "Te_Whenua_Plant_Rimu_Leaves",
      "support": 15
    },
    {
      "x": -2,
      "y": 11,
      "z": 1,
      "name": "Te_Whenua_Plant_Rimu_Leaves",
      "support": 15
    },
    {
      "x": -2,
      "y": 12,
      "z": 1,
      "name": "Te_Whenua_Plant_Rimu_Leaves",
      "support": 15
    },
    {
      "x": -2,
      "y": 14,
      "z": 1,
      "name": "Te_Whenua_Plant_Rimu_Leaves",
      "support": 15
    },
    {
      "x": -2,
      "y": 16,
      "z": 1,
      "name": "Te_Whenua_Plant_Rimu_Leaves",
      "support": 15
    },
    {
      "x": -2,
      "y": 9,
      "z": 2,
      "name": "Te_Whenua_Plant_Rimu_Leaves",
      "support": 15
    },
    {
      "x": -2,
      "y": 11,
      "z": 2,
      "name": "Te_Whenua_Plant_Rimu_Leaves",
      "support": 15
    },
    {
      "x": -1,
      "y": 9,
      "z": -3,
      "name": "Te_Whenua_Plant_Rimu_Leaves",
      "support": 15
    },
    {
      "x": -1,
      "y": 10,
      "z": -3,
      "name": "Te_Whenua_Plant_Rimu_Leaves",
      "support": 15
    },
    {
      "x": -1,
      "y": 0,
      "z": -2,
      "name": "Te_Whenua_Wood_Rimu_Trunk",
      "support": 15
    },
    {
      "x": -1,
      "y": 1,
      "z": -2,
      "name": "Te_Whenua_Wood_Rimu_Trunk",
      "support": 15
    },
    {
      "x": -1,
      "y": 2,
      "z": -2,
      "name": "Te_Whenua_Wood_Rimu_Trunk_Full",
      "support": 15
    },
    {
      "x": -1,
      "y": 9,
      "z": -2,
      "name": "Te_Whenua_Plant_Rimu_Leaves",
      "support": 15
    },
    {
      "x": -1,
      "y": 10,
      "z": -2,
      "name": "Te_Whenua_Plant_Rimu_Leaves",
      "support": 15
    },
    {
      "x": -1,
      "y": 11,
      "z": -2,
      "name": "Te_Whenua_Plant_Rimu_Leaves",
      "support": 15
    },
    {
      "x": -1,
      "y": 12,
      "z": -2,
      "name": "Te_Whenua_Plant_Rimu_Leaves",
      "support": 15
    },
    {
      "x": -1,
      "y": 15,
      "z": -2,
      "name": "Te_Whenua_Plant_Rimu_Leaves",
      "support": 15
    },
    {
      "x": -1,
      "y": 0,
      "z": -1,
      "name": "Te_Whenua_Wood_Rimu_Trunk",
      "support": 15
    },
    {
      "x": -1,
      "y": 1,
      "z": -1,
      "name": "Te_Whenua_Wood_Rimu_Trunk",
      "support": 15
    },
    {
      "x": -1,
      "y": 2,
      "z": -1,
      "name": "Te_Whenua_Wood_Rimu_Trunk",
      "support": 15
    },
    {
      "x": -1,
      "y": 3,
      "z": -1,
      "name": "Te_Whenua_Wood_Rimu_Trunk",
      "support": 15
    },
    {
      "x": -1,
      "y": 4,
      "z": -1,
      "name": "Te_Whenua_Wood_Rimu_Trunk_Full",
      "support": 15
    },
    {
      "x": -1,
      "y": 7,
      "z": -1,
      "name": "Te_Whenua_Plant_Rimu_Leaves",
      "support": 15
    },
    {
      "x": -1,
      "y": 8,
      "z": -1,
      "name": "Te_Whenua_Plant_Rimu_Leaves",
      "support": 15
    },
    {
      "x": -1,
      "y": 9,
      "z": -1,
      "name": "Te_Whenua_Plant_Rimu_Leaves",
      "support": 15
    },
    {
      "x": -1,
      "y": 10,
      "z": -1,
      "name": "Te_Whenua_Plant_Rimu_Leaves",
      "support": 15
    },
    {
      "x": -1,
      "y": 11,
      "z": -1,
      "name": "Te_Whenua_Plant_Rimu_Leaves",
      "support": 15
    },
    {
      "x": -1,
      "y": 12,
      "z": -1,
      "name": "Te_Whenua_Plant_Rimu_Leaves",
      "support": 15
    },
    {
      "x": -1,
      "y": 13,
      "z": -1,
      "name": "Te_Whenua_Plant_Rimu_Leaves",
      "support": 15
    },
    {
      "x": -1,
      "y": 15,
      "z": -1,
      "name": "Te_Whenua_Plant_Rimu_Leaves",
      "support": 15
    },
    {
      "x": -1,
      "y": 16,
      "z": -1,
      "name": "Te_Whenua_Plant_Rimu_Leaves",
      "support": 15
    },
    {
      "x": -1,
      "y": 17,
      "z": -1,
      "name": "Te_Whenua_Plant_Rimu_Leaves",
      "support": 15
    },
    {
      "x": -1,
      "y": 0,
      "z": 0,
      "name": "Te_Whenua_Wood_Rimu_Trunk",
      "support": 15
    },
    {
      "x": -1,
      "y": 1,
      "z": 0,
      "name": "Te_Whenua_Wood_Rimu_Trunk",
      "support": 15
    },
    {
      "x": -1,
      "y": 2,
      "z": 0,
      "name": "Te_Whenua_Wood_Rimu_Trunk",
      "support": 15
    },
    {
      "x": -1,
      "y": 3,
      "z": 0,
      "name": "Te_Whenua_Wood_Rimu_Trunk",
      "support": 15
    },
    {
      "x": -1,
      "y": 4,
      "z": 0,
      "name": "Te_Whenua_Wood_Rimu_Trunk",
      "support": 15
    },
    {
      "x": -1,
      "y": 5,
      "z": 0,
      "name": "Te_Whenua_Wood_Rimu_Trunk",
      "support": 15
    },
    {
      "x": -1,
      "y": 6,
      "z": 0,
      "name": "Te_Whenua_Wood_Rimu_Trunk",
      "support": 15
    },
    {
      "x": -1,
      "y": 7,
      "z": 0,
      "name": "Te_Whenua_Wood_Rimu_Trunk",
      "support": 15
    },
    {
      "x": -1,
      "y": 8,
      "z": 0,
      "name": "Te_Whenua_Wood_Rimu_Trunk",
      "support": 15
    },
    {
      "x": -1,
      "y": 9,
      "z": 0,
      "name": "Te_Whenua_Wood_Rimu_Trunk",
      "support": 15
    },
    {
      "x": -1,
      "y": 10,
      "z": 0,
      "name": "Te_Whenua_Wood_Rimu_Trunk",
      "support": 15
    },
    {
      "x": -1,
      "y": 11,
      "z": 0,
      "name": "Te_Whenua_Wood_Rimu_Trunk_Full",
      "support": 15
    },
    {
      "x": -1,
      "y": 12,
      "z": 0,
      "name": "Te_Whenua_Plant_Rimu_Leaves",
      "support": 15
    },
    {
      "x": -1,
      "y": 13,
      "z": 0,
      "name": "Te_Whenua_Plant_Rimu_Leaves",
      "support": 15
    },
    {
      "x": -1,
      "y": 14,
      "z": 0,
      "name": "Te_Whenua_Plant_Rimu_Leaves",
      "support": 15
    },
    {
      "x": -1,
      "y": 15,
      "z": 0,
      "name": "Te_Whenua_Plant_Rimu_Leaves",
      "support": 15
    },
    {
      "x": -1,
      "y": 16,
      "z": 0,
      "name": "Te_Whenua_Wood_Rimu_Branch_Long",
      "support": 15,
      "rotation": 5
    },
    {
      "x": -1,
      "y": 17,
      "z": 0,
      "name": "Te_Whenua_Plant_Rimu_Leaves",
      "support": 15
    },
    {
      "x": -1,
      "y": 7,
      "z": 1,
      "name": "Te_Whenua_Wood_Rimu_Branch_Short",
      "support": 15
    },
    {
      "x": -1,
      "y": 8,
      "z": 1,
      "name": "Te_Whenua_Plant_Rimu_Leaves",
      "support": 15
    },
    {
      "x": -1,
      "y": 9,
      "z": 1,
      "name": "Te_Whenua_Plant_Rimu_Leaves",
      "support": 15
    },
    {
      "x": -1,
      "y": 10,
      "z": 1,
      "name": "Te_Whenua_Plant_Rimu_Leaves",
      "support": 15
    },
    {
      "x": -1,
      "y": 11,
      "z": 1,
      "name": "Te_Whenua_Wood_Rimu_Branch_Long",
      "support": 15,
      "rotation": 4
    },
    {
      "x": -1,
      "y": 12,
      "z": 1,
      "name": "Te_Whenua_Plant_Rimu_Leaves",
      "support": 15
    },
    {
      "x": -1,
      "y": 13,
      "z": 1,
      "name": "Te_Whenua_Plant_Rimu_Leaves",
      "support": 15
    },
    {
      "x": -1,
      "y": 14,
      "z": 1,
      "name": "Te_Whenua_Plant_Rimu_Leaves",
      "support": 15
    },
    {
      "x": -1,
      "y": 15,
      "z": 1,
      "name": "Te_Whenua_Plant_Rimu_Leaves",
      "support": 15
    },
    {
      "x": -1,
      "y": 16,
      "z": 1,
      "name": "Te_Whenua_Plant_Rimu_Leaves",
      "support": 15
    },
    {
      "x": -1,
      "y": 17,
      "z": 1,
      "name": "Te_Whenua_Plant_Rimu_Leaves",
      "support": 15
    },
    {
      "x": -1,
      "y": 18,
      "z": 1,
      "name": "Te_Whenua_Plant_Rimu_Leaves",
      "support": 15
    },
    {
      "x": -1,
      "y": 9,
      "z": 2,
      "name": "Te_Whenua_Plant_Rimu_Leaves",
      "support": 15
    },
    {
      "x": -1,
      "y": 10,
      "z": 2,
      "name": "Te_Whenua_Plant_Rimu_Leaves",
      "support": 15
    },
    {
      "x": -1,
      "y": 11,
      "z": 2,
      "name": "Te_Whenua_Plant_Rimu_Leaves",
      "support": 15
    },
    {
      "x": -1,
      "y": 12,
      "z": 2,
      "name": "Te_Whenua_Plant_Rimu_Leaves",
      "support": 15
    },
    {
      "x": -1,
      "y": 9,
      "z": 3,
      "name": "Te_Whenua_Plant_Rimu_Leaves",
      "support": 15
    },
    {
      "x": -1,
      "y": 10,
      "z": 3,
      "name": "Te_Whenua_Plant_Rimu_Leaves",
      "support": 15
    },
    {
      "x": -1,
      "y": 11,
      "z": 3,
      "name": "Te_Whenua_Plant_Rimu_Leaves",
      "support": 15
    },
    {
      "x": 0,
      "y": 8,
      "z": -3,
      "name": "Te_Whenua_Plant_Rimu_Leaves",
      "support": 15
    },
    {
      "x": 0,
      "y": 9,
      "z": -3,
      "name": "Te_Whenua_Plant_Rimu_Leaves",
      "support": 15
    },
    {
      "x": 0,
      "y": 10,
      "z": -3,
      "name": "Te_Whenua_Plant_Rimu_Leaves",
      "support": 15
    },
    {
      "x": 0,
      "y": 11,
      "z": -3,
      "name": "Te_Whenua_Plant_Rimu_Leaves",
      "support": 15
    },
    {
      "x": 0,
      "y": 6,
      "z": -2,
      "name": "Te_Whenua_Wood_Rimu_Branch_Long",
      "support": 15,
      "rotation": 4
    },
    {
      "x": 0,
      "y": 7,
      "z": -2,
      "name": "Te_Whenua_Plant_Rimu_Leaves",
      "support": 15
    },
    {
      "x": 0,
      "y": 8,
      "z": -2,
      "name": "Te_Whenua_Plant_Rimu_Leaves",
      "support": 15
    },
    {
      "x": 0,
      "y": 9,
      "z": -2,
      "name": "Te_Whenua_Plant_Rimu_Leaves",
      "support": 15
    },
    {
      "x": 0,
      "y": 10,
      "z": -2,
      "name": "Te_Whenua_Wood_Rimu_Branch_Long",
      "support": 15,
      "rotation": 4
    },
    {
      "x": 0,
      "y": 11,
      "z": -2,
      "name": "Te_Whenua_Plant_Rimu_Leaves",
      "support": 15
    },
    {
      "x": 0,
      "y": 12,
      "z": -2,
      "name": "Te_Whenua_Plant_Rimu_Leaves",
      "support": 15
    },
    {
      "x": 0,
      "y": 13,
      "z": -2,
      "name": "Te_Whenua_Plant_Rimu_Leaves",
      "support": 15
    },
    {
      "x": 0,
      "y": 14,
      "z": -2,
      "name": "Te_Whenua_Plant_Rimu_Leaves",
      "support": 15
    },
    {
      "x": 0,
      "y": 15,
      "z": -2,
      "name": "Te_Whenua_Plant_Rimu_Leaves",
      "support": 15
    },
    {
      "x": 0,
      "y": 16,
      "z": -2,
      "name": "Te_Whenua_Plant_Rimu_Leaves",
      "support": 15
    },
    {
      "x": 0,
      "y": 0,
      "z": -1,
      "name": "Te_Whenua_Wood_Rimu_Trunk",
      "support": 15
    },
    {
      "x": 0,
      "y": 1,
      "z": -1,
      "name": "Te_Whenua_Wood_Rimu_Trunk",
      "support": 15
    },
    {
      "x": 0,
      "y": 2,
      "z": -1,
      "name": "Te_Whenua_Wood_Rimu_Trunk",
      "support": 15
    },
    {
      "x": 0,
      "y": 3,
      "z": -1,
      "name": "Te_Whenua_Wood_Rimu_Trunk",
      "support": 15
    },
    {
      "x": 0,
      "y": 4,
      "z": -1,
      "name": "Te_Whenua_Wood_Rimu_Trunk",
      "support": 15
    },
    {
      "x": 0,
      "y": 5,
      "z": -1,
      "name": "Te_Whenua_Wood_Rimu_Trunk",
      "support": 15
    },
    {
      "x": 0,
      "y": 6,
      "z": -1,
      "name": "Te_Whenua_Wood_Rimu_Trunk",
      "support": 15
    },
    {
      "x": 0,
      "y": 7,
      "z": -1,
      "name": "Te_Whenua_Wood_Rimu_Trunk",
      "support": 15
    },
    {
      "x": 0,
      "y": 8,
      "z": -1,
      "name": "Te_Whenua_Wood_Rimu_Trunk",
      "support": 15
    },
    {
      "x": 0,
      "y": 9,
      "z": -1,
      "name": "Te_Whenua_Wood_Rimu_Trunk_Full",
      "support": 15
    },
    {
      "x": 0,
      "y": 10,
      "z": -1,
      "name": "Te_Whenua_Wood_Rimu_Branch_Long",
      "support": 15,
      "rotation": 4
    },
    {
      "x": 0,
      "y": 11,
      "z": -1,
      "name": "Te_Whenua_Plant_Rimu_Leaves",
      "support": 15
    },
    {
      "x": 0,
      "y": 12,
      "z": -1,
      "name": "Te_Whenua_Plant_Rimu_Leaves",
      "support": 15
    },
    {
      "x": 0,
      "y": 13,
      "z": -1,
      "name": "Te_Whenua_Plant_Rimu_Leaves",
      "support": 15
    },
    {
      "x": 0,
      "y": 14,
      "z": -1,
      "name": "Te_Whenua_Plant_Rimu_Leaves",
      "support": 15
    },
    {
      "x": 0,
      "y": 15,
      "z": -1,
      "name": "Te_Whenua_Plant_Rimu_Leaves",
      "support": 15
    },
    {
      "x": 0,
      "y": 16,
      "z": -1,
      "name": "Te_Whenua_Plant_Rimu_Leaves",
      "support": 15
    },
    {
      "x": 0,
      "y": 17,
      "z": -1,
      "name": "Te_Whenua_Plant_Rimu_Leaves",
      "support": 15
    },
    {
      "x": 0,
      "y": 18,
      "z": -1,
      "name": "Te_Whenua_Plant_Rimu_Leaves",
      "support": 15
    },
    {
      "x": 0,
      "y": 19,
      "z": -1,
      "name": "Te_Whenua_Plant_Rimu_Leaves",
      "support": 15
    },
    {
      "x": 0,
      "y": 0,
      "z": 0,
      "name": "Te_Whenua_Wood_Rimu_Trunk",
      "support": 15
    },
    {
      "x": 0,
      "y": 1,
      "z": 0,
      "name": "Te_Whenua_Wood_Rimu_Trunk",
      "support": 15
    },
    {
      "x": 0,
      "y": 2,
      "z": 0,
      "name": "Te_Whenua_Wood_Rimu_Trunk",
      "support": 15
    },
    {
      "x": 0,
      "y": 3,
      "z": 0,
      "name": "Te_Whenua_Wood_Rimu_Trunk",
      "support": 15
    },
    {
      "x": 0,
      "y": 4,
      "z": 0,
      "name": "Te_Whenua_Wood_Rimu_Trunk",
      "support": 15
    },
    {
      "x": 0,
      "y": 5,
      "z": 0,
      "name": "Te_Whenua_Wood_Rimu_Trunk",
      "support": 15
    },
    {
      "x": 0,
      "y": 6,
      "z": 0,
      "name": "Te_Whenua_Wood_Rimu_Trunk",
      "support": 15
    },
    {
      "x": 0,
      "y": 7,
      "z": 0,
      "name": "Te_Whenua_Wood_Rimu_Trunk",
      "support": 15
    },
    {
      "x": 0,
      "y": 8,
      "z": 0,
      "name": "Te_Whenua_Wood_Rimu_Trunk",
      "support": 15
    },
    {
      "x": 0,
      "y": 9,
      "z": 0,
      "name": "Te_Whenua_Wood_Rimu_Trunk",
      "support": 15
    },
    {
      "x": 0,
      "y": 10,
      "z": 0,
      "name": "Te_Whenua_Wood_Rimu_Trunk",
      "support": 15
    },
    {
      "x": 0,
      "y": 11,
      "z": 0,
      "name": "Te_Whenua_Wood_Rimu_Trunk",
      "support": 15
    },
    {
      "x": 0,
      "y": 12,
      "z": 0,
      "name": "Te_Whenua_Wood_Rimu_Trunk",
      "support": 15
    },
    {
      "x": 0,
      "y": 13,
      "z": 0,
      "name": "Te_Whenua_Wood_Rimu_Trunk",
      "support": 15
    },
    {
      "x": 0,
      "y": 14,
      "z": 0,
      "name": "Te_Whenua_Wood_Rimu_Trunk",
      "support": 15
    },
    {
      "x": 0,
      "y": 15,
      "z": 0,
      "name": "Te_Whenua_Wood_Rimu_Trunk",
      "support": 15
    },
    {
      "x": 0,
      "y": 16,
      "z": 0,
      "name": "Te_Whenua_Wood_Rimu_Trunk",
      "support": 15
    },
    {
      "x": 0,
      "y": 17,
      "z": 0,
      "name": "Te_Whenua_Wood_Rimu_Trunk",
      "support": 15
    },
    {
      "x": 0,
      "y": 18,
      "z": 0,
      "name": "Te_Whenua_Plant_Rimu_Leaves",
      "support": 15
    },
    {
      "x": 0,
      "y": 19,
      "z": 0,
      "name": "Te_Whenua_Plant_Rimu_Leaves",
      "support": 15
    },
    {
      "x": 0,
      "y": 20,
      "z": 0,
      "name": "Te_Whenua_Plant_Rimu_Leaves",
      "support": 15
    },
    {
      "x": 0,
      "y": 0,
      "z": 1,
      "name": "Te_Whenua_Wood_Rimu_Trunk",
      "support": 15
    },
    {
      "x": 0,
      "y": 1,
      "z": 1,
      "name": "Te_Whenua_Wood_Rimu_Trunk",
      "support": 15
    },
    {
      "x": 0,
      "y": 2,
      "z": 1,
      "name": "Te_Whenua_Wood_Rimu_Trunk_Full",
      "support": 15
    },
    {
      "x": 0,
      "y": 9,
      "z": 1,
      "name": "Te_Whenua_Plant_Rimu_Leaves",
      "support": 15
    },
    {
      "x": 0,
      "y": 10,
      "z": 1,
      "name": "Te_Whenua_Plant_Rimu_Leaves",
      "support": 15
    },
    {
      "x": 0,
      "y": 11,
      "z": 1,
      "name": "Te_Whenua_Plant_Rimu_Leaves",
      "support": 15
    },
    {
      "x": 0,
      "y": 12,
      "z": 1,
      "name": "Te_Whenua_Plant_Rimu_Leaves",
      "support": 15
    },
    {
      "x": 0,
      "y": 13,
      "z": 1,
      "name": "Te_Whenua_Plant_Rimu_Leaves",
      "support": 15
    },
    {
      "x": 0,
      "y": 14,
      "z": 1,
      "name": "Te_Whenua_Plant_Rimu_Leaves",
      "support": 15
    },
    {
      "x": 0,
      "y": 15,
      "z": 1,
      "name": "Te_Whenua_Plant_Rimu_Leaves",
      "support": 15
    },
    {
      "x": 0,
      "y": 16,
      "z": 1,
      "name": "Te_Whenua_Plant_Rimu_Leaves",
      "support": 15
    },
    {
      "x": 0,
      "y": 17,
      "z": 1,
      "name": "Te_Whenua_Wood_Rimu_Branch_Corner",
      "support": 15
    },
    {
      "x": 0,
      "y": 18,
      "z": 1,
      "name": "Te_Whenua_Wood_Rimu_Branch_Long",
      "support": 15
    },
    {
      "x": 0,
      "y": 19,
      "z": 1,
      "name": "Te_Whenua_Plant_Rimu_Leaves",
      "support": 15
    },
    {
      "x": 0,
      "y": 9,
      "z": 2,
      "name": "Te_Whenua_Plant_Rimu_Leaves",
      "support": 15
    },
    {
      "x": 0,
      "y": 10,
      "z": 2,
      "name": "Te_Whenua_Plant_Rimu_Leaves",
      "support": 15
    },
    {
      "x": 0,
      "y": 11,
      "z": 2,
      "name": "Te_Whenua_Plant_Rimu_Leaves",
      "support": 15
    },
    {
      "x": 0,
      "y": 12,
      "z": 2,
      "name": "Te_Whenua_Plant_Rimu_Leaves",
      "support": 15
    },
    {
      "x": 0,
      "y": 13,
      "z": 2,
      "name": "Te_Whenua_Plant_Rimu_Leaves",
      "support": 15
    },
    {
      "x": 0,
      "y": 14,
      "z": 2,
      "name": "Te_Whenua_Plant_Rimu_Leaves",
      "support": 15
    },
    {
      "x": 0,
      "y": 17,
      "z": 2,
      "name": "Te_Whenua_Plant_Rimu_Leaves",
      "support": 15
    },
    {
      "x": 0,
      "y": 18,
      "z": 2,
      "name": "Te_Whenua_Plant_Rimu_Leaves",
      "support": 15
    },
    {
      "x": 0,
      "y": 10,
      "z": 3,
      "name": "Te_Whenua_Plant_Rimu_Leaves",
      "support": 15
    },
    {
      "x": 0,
      "y": 11,
      "z": 3,
      "name": "Te_Whenua_Plant_Rimu_Leaves",
      "support": 15
    },
    {
      "x": 1,
      "y": 9,
      "z": -3,
      "name": "Te_Whenua_Plant_Rimu_Leaves",
      "support": 15
    },
    {
      "x": 1,
      "y": 10,
      "z": -3,
      "name": "Te_Whenua_Plant_Rimu_Leaves",
      "support": 15
    },
    {
      "x": 1,
      "y": 7,
      "z": -2,
      "name": "Te_Whenua_Plant_Rimu_Leaves",
      "support": 15
    },
    {
      "x": 1,
      "y": 9,
      "z": -2,
      "name": "Te_Whenua_Plant_Rimu_Leaves",
      "support": 15
    },
    {
      "x": 1,
      "y": 10,
      "z": -2,
      "name": "Te_Whenua_Plant_Rimu_Leaves",
      "support": 15
    },
    {
      "x": 1,
      "y": 11,
      "z": -2,
      "name": "Te_Whenua_Plant_Rimu_Leaves",
      "support": 15
    },
    {
      "x": 1,
      "y": 12,
      "z": -2,
      "name": "Te_Whenua_Plant_Rimu_Leaves",
      "support": 15
    },
    {
      "x": 1,
      "y": 15,
      "z": -2,
      "name": "Te_Whenua_Plant_Rimu_Leaves",
      "support": 15
    },
    {
      "x": 1,
      "y": 7,
      "z": -1,
      "name": "Te_Whenua_Plant_Rimu_Leaves",
      "support": 15
    },
    {
      "x": 1,
      "y": 8,
      "z": -1,
      "name": "Te_Whenua_Plant_Rimu_Leaves",
      "support": 15
    },
    {
      "x": 1,
      "y": 9,
      "z": -1,
      "name": "Te_Whenua_Plant_Rimu_Leaves",
      "support": 15
    },
    {
      "x": 1,
      "y": 10,
      "z": -1,
      "name": "Te_Whenua_Plant_Rimu_Leaves",
      "support": 15
    },
    {
      "x": 1,
      "y": 11,
      "z": -1,
      "name": "Te_Whenua_Plant_Rimu_Leaves",
      "support": 15
    },
    {
      "x": 1,
      "y": 12,
      "z": -1,
      "name": "Te_Whenua_Plant_Rimu_Leaves",
      "support": 15
    },
    {
      "x": 1,
      "y": 13,
      "z": -1,
      "name": "Te_Whenua_Plant_Rimu_Leaves",
      "support": 15
    },
    {
      "x": 1,
      "y": 14,
      "z": -1,
      "name": "Te_Whenua_Plant_Rimu_Leaves",
      "support": 15
    },
    {
      "x": 1,
      "y": 15,
      "z": -1,
      "name": "Te_Whenua_Plant_Rimu_Leaves",
      "support": 15
    },
    {
      "x": 1,
      "y": 17,
      "z": -1,
      "name": "Te_Whenua_Plant_Rimu_Leaves",
      "support": 15
    },
    {
      "x": 1,
      "y": 18,
      "z": -1,
      "name": "Te_Whenua_Plant_Rimu_Leaves",
      "support": 15
    },
    {
      "x": 1,
      "y": 0,
      "z": 0,
      "name": "Te_Whenua_Wood_Rimu_Trunk",
      "support": 15
    },
    {
      "x": 1,
      "y": 1,
      "z": 0,
      "name": "Te_Whenua_Wood_Rimu_Trunk_Full",
      "support": 15
    },
    {
      "x": 1,
      "y": 6,
      "z": 0,
      "name": "Te_Whenua_Wood_Rimu_Branch_Short",
      "support": 15,
      "rotation": 1
    },
    {
      "x": 1,
      "y": 8,
      "z": 0,
      "name": "Te_Whenua_Plant_Rimu_Leaves",
      "support": 15
    },
    {
      "x": 1,
      "y": 9,
      "z": 0,
      "name": "Te_Whenua_Plant_Rimu_Leaves",
      "support": 15
    },
    {
      "x": 1,
      "y": 10,
      "z": 0,
      "name": "Te_Whenua_Plant_Rimu_Leaves",
      "support": 15
    },
    {
      "x": 1,
      "y": 11,
      "z": 0,
      "name": "Te_Whenua_Plant_Rimu_Leaves",
      "support": 15
    },
    {
      "x": 1,
      "y": 12,
      "z": 0,
      "name": "Te_Whenua_Plant_Rimu_Leaves",
      "support": 15
    },
    {
      "x": 1,
      "y": 13,
      "z": 0,
      "name": "Te_Whenua_Plant_Rimu_Leaves",
      "support": 15
    },
    {
      "x": 1,
      "y": 14,
      "z": 0,
      "name": "Te_Whenua_Wood_Rimu_Branch_Long",
      "support": 15,
      "rotation": 5
    },
    {
      "x": 1,
      "y": 15,
      "z": 0,
      "name": "Te_Whenua_Plant_Rimu_Leaves",
      "support": 15
    },
    {
      "x": 1,
      "y": 16,
      "z": 0,
      "name": "Te_Whenua_Plant_Rimu_Leaves",
      "support": 15
    },
    {
      "x": 1,
      "y": 17,
      "z": 0,
      "name": "Te_Whenua_Plant_Rimu_Leaves",
      "support": 15
    },
    {
      "x": 1,
      "y": 9,
      "z": 1,
      "name": "Te_Whenua_Plant_Rimu_Leaves",
      "support": 15
    },
    {
      "x": 1,
      "y": 10,
      "z": 1,
      "name": "Te_Whenua_Plant_Rimu_Leaves",
      "support": 15
    },
    {
      "x": 1,
      "y": 11,
      "z": 1,
      "name": "Te_Whenua_Plant_Rimu_Leaves",
      "support": 15
    },
    {
      "x": 1,
      "y": 12,
      "z": 1,
      "name": "Te_Whenua_Plant_Rimu_Leaves",
      "support": 15
    },
    {
      "x": 1,
      "y": 13,
      "z": 1,
      "name": "Te_Whenua_Plant_Rimu_Leaves",
      "support": 15
    },
    {
      "x": 1,
      "y": 14,
      "z": 1,
      "name": "Te_Whenua_Plant_Rimu_Leaves",
      "support": 15
    },
    {
      "x": 1,
      "y": 15,
      "z": 1,
      "name": "Te_Whenua_Plant_Rimu_Leaves",
      "support": 15
    },
    {
      "x": 1,
      "y": 17,
      "z": 1,
      "name": "Te_Whenua_Plant_Rimu_Leaves",
      "support": 15
    },
    {
      "x": 1,
      "y": 18,
      "z": 1,
      "name": "Te_Whenua_Plant_Rimu_Leaves",
      "support": 15
    },
    {
      "x": 1,
      "y": 9,
      "z": 2,
      "name": "Te_Whenua_Plant_Rimu_Leaves",
      "support": 15
    },
    {
      "x": 1,
      "y": 10,
      "z": 2,
      "name": "Te_Whenua_Plant_Rimu_Leaves",
      "support": 15
    },
    {
      "x": 1,
      "y": 11,
      "z": 2,
      "name": "Te_Whenua_Plant_Rimu_Leaves",
      "support": 15
    },
    {
      "x": 1,
      "y": 12,
      "z": 2,
      "name": "Te_Whenua_Plant_Rimu_Leaves",
      "support": 15
    },
    {
      "x": 1,
      "y": 9,
      "z": 3,
      "name": "Te_Whenua_Plant_Rimu_Leaves",
      "support": 15
    },
    {
      "x": 1,
      "y": 10,
      "z": 3,
      "name": "Te_Whenua_Plant_Rimu_Leaves",
      "support": 15
    },
    {
      "x": 2,
      "y": 10,
      "z": -1,
      "name": "Te_Whenua_Plant_Rimu_Leaves",
      "support": 15
    },
    {
      "x": 2,
      "y": 11,
      "z": -1,
      "name": "Te_Whenua_Plant_Rimu_Leaves",
      "support": 15
    },
    {
      "x": 2,
      "y": 14,
      "z": -1,
      "name": "Te_Whenua_Plant_Rimu_Leaves",
      "support": 15
    },
    {
      "x": 2,
      "y": 15,
      "z": -1,
      "name": "Te_Whenua_Plant_Rimu_Leaves",
      "support": 15
    },
    {
      "x": 2,
      "y": 9,
      "z": 0,
      "name": "Te_Whenua_Plant_Rimu_Leaves",
      "support": 15
    },
    {
      "x": 2,
      "y": 10,
      "z": 0,
      "name": "Te_Whenua_Plant_Rimu_Leaves",
      "support": 15
    },
    {
      "x": 2,
      "y": 11,
      "z": 0,
      "name": "Te_Whenua_Plant_Rimu_Leaves",
      "support": 15
    },
    {
      "x": 2,
      "y": 12,
      "z": 0,
      "name": "Te_Whenua_Plant_Rimu_Leaves",
      "support": 15
    },
    {
      "x": 2,
      "y": 13,
      "z": 0,
      "name": "Te_Whenua_Plant_Rimu_Leaves",
      "support": 15
    },
    {
      "x": 2,
      "y": 14,
      "z": 0,
      "name": "Te_Whenua_Plant_Rimu_Leaves",
      "support": 15
    },
    {
      "x": 2,
      "y": 15,
      "z": 0,
      "name": "Te_Whenua_Plant_Rimu_Leaves",
      "support": 15
    },
    {
      "x": 2,
      "y": 16,
      "z": 0,
      "name": "Te_Whenua_Plant_Rimu_Leaves",
      "support": 15
    },
    {
      "x": 2,
      "y": 9,
      "z": 1,
      "name": "Te_Whenua_Plant_Rimu_Leaves",
      "support": 15
    },
    {
      "x": 2,
      "y": 11,
      "z": 1,
      "name": "Te_Whenua_Plant_Rimu_Leaves",
      "support": 15
    },
    {
      "x": 2,
      "y": 12,
      "z": 1,
      "name": "Te_Whenua_Plant_Rimu_Leaves",
      "support": 15
    },
    {
      "x": 2,
      "y": 14,
      "z": 1,
      "name": "Te_Whenua_Plant_Rimu_Leaves",
      "support": 15
    },
    {
      "x": 3,
      "y": 10,
      "z": -1,
      "name": "Te_Whenua_Plant_Rimu_Leaves",
      "support": 15
    },
    {
      "x": 3,
      "y": 9,
      "z": 0,
      "name": "Te_Whenua_Plant_Rimu_Leaves",
      "support": 15
    },
    {
      "x": 3,
      "y": 11,
      "z": 0,
      "name": "Te_Whenua_Plant_Rimu_Leaves",
      "support": 15
    },
    {
      "x": 3,
      "y": 14,
      "z": 0,
      "name": "Te_Whenua_Plant_Rimu_Leaves",
      "support": 15
    },
    {
      "x": 3,
      "y": 15,
      "z": 0,
      "name": "Te_Whenua_Plant_Rimu_Leaves",
      "support": 15
    }
  ]
}